Workbook
Name ALL: #REF!
Name ALLP: #REF!
Name COST: #REF!
Name Markets: #REF!
Name MAT: #REF!
Name Print_Area_MI: #REF!
Name PUR: #REF!
Name SUM: #REF!

Sheet P
B1: 1-100 MATERIALS | C1: 2-100 LABOR | D1: 4-100 SUBCONTRACTOR | E1: 7-100 AIRLINE EXPENSES | F1: 7-200 HOTEL EXPENSES | G1: 7-300 AUTO RENTAL | H1: 7-400 MILEAGE/FUEL EXPENSE | I1: 7-600 PARKING / TOLLS | J1: 7-750 PER DIEM (TRAVEL DAYS) | K1: 7-760 PER DIEM (WORK DAYS) | L1: 7-770 TRAVEL PAY | M1: 5-000 OTHER COSTS | N1: 5-100 FREIGHT | O1: 5-100 RETURN FREIGHT | P1: 5-300 RENTALS | Q1: CA LITIGATION FUND | R1: 5-900 MISC. EXPENSES | S1: 5-901 CONTINGENCY | T1: TAX % | U1: Total | V1: MARK UP $ | X1: Product # | Y1: Description | Z1: Cost | AA1: Unit Size | AB1: Weight | AC1: Color | AD1: B:B | AE1: C:C | AF1: D:D | AG1: L:L | AH1: M:M | AI1: N:N | AJ1: Total Qty | AK1: USD | AL1: USD | AM1: 1 | AN1: Product # | AO1: Description | AP1: Cost | AQ1: Unit Size | AR1: Weight | AS1: Color | AT1: PRODUCT | AU1: UOM | AV1: LOOKUP COMBO | AW1: PRICE | AY1: PROD ID | AZ1: PRODUCT | BA1: COLOR | BB1: UOM | BC1: PRICE | BD1: PRODUCT | BE1: COLOR | BF1: UOM | BG1: CATEGORY | BH1: PATCH | BI1: 1/2 GAL | BJ1: DESCRIPTION | BK1: CATEGORY | BL1: DESCRIPTION | BM1: CATEGORY | BN1: DESCRIPTION | BO1: CATEGORY
A2: RIO | B2: =IFERROR(VLOOKUP(B$1,SGC!$C:$D,2,FALSE),0) -> 0 | C2: =IFERROR(VLOOKUP(C$1,SGC!$C:$D,2,FALSE),0) -> 0 | D2: =IFERROR(VLOOKUP(D$1,SGC!$C:$D,2,FALSE),0) -> 0 | E2: =IFERROR(VLOOKUP(E$1,SGC!$C:$D,2,FALSE),0) -> 0 | F2: =IFERROR(VLOOKUP(F$1,SGC!$C:$D,2,FALSE),0) -> 0 | G2: =IFERROR(VLOOKUP(G$1,SGC!$C:$D,2,FALSE),0) -> 0 | H2: =IFERROR(VLOOKUP(H$1,SGC!$C:$D,2,FALSE),0) -> 0 | I2: =IFERROR(VLOOKUP(I$1,SGC!$C:$D,2,FALSE),0) -> 0 | J2: =IFERROR(VLOOKUP(J$1,SGC!$F:$H,3,FALSE),0) -> 0 | K2: =IFERROR(VLOOKUP(K$1,SGC!$F:$H,3,FALSE),0) -> 0 | L2: =IFERROR(VLOOKUP(L$1,SGC!$F:$H,3,FALSE),0) -> 0 | M2: =IFERROR(VLOOKUP(M$1,SGC!$F:$H,3,FALSE),0) -> 0 | N2: =IFERROR(VLOOKUP(N$1,SGC!$F:$H,3,FALSE),0) -> 0 | O2: =IFERROR(VLOOKUP(O$1,SGC!$F:$H,3,FALSE),0) -> 0 | P2: =IFERROR(VLOOKUP(P$1,SGC!$F:$H,3,FALSE),0) -> 0 | Q2: =IFERROR(VLOOKUP(Q$1,SGC!$C:$D,2,FALSE),0) -> 0 | R2: =IFERROR(VLOOKUP(R$1,SGC!$F:$H,3,FALSE),0) -> 0 | S2: =IFERROR(VLOOKUP(S$1,SGC!$F:$H,3,FALSE),0) -> 0 | T2: =SUM(SGC!N78:O80) -> 0 | U2: =VLOOKUP("CUSTOMER BID AMOUNT*",SGC!$M:$Q,5,FALSE) -> 0 | V2: =IFERROR(VLOOKUP(V$1,SGC!$P:$R,3,FALSE),0) -> 0 | W2: RS88 | X2: FIBERTAPE | Y2: FIBERGLASS TAPE 6"X75 FT | Z2: =Table1[[#This Row],[D:D]] -> 33.1782 | AA2: Roll | AD2: RIO | AE2: 30.162 | AF2: =Table1[[#This Row],[C:C]]*1.1 -> 33.1782 | AI2: =IFERROR(VLOOKUP(X2,#REF!,8,FALSE),0) -> 0 | AK2: CAD | AL2: #VALUE! | AM2: {=_FV(AL2,"Price")} -> 1.3733 | AN2: =PROD_ID_TABLE[[#This Row],[PROD ID]] -> 3500 EPOXYN//A1/2 | AO2: =_xlfn.CONCAT(BD2:BF2) -> RESUFLOR 3500 EPOXY QUICK PATCH (FAST)N/A1/2 GAL | AP2: =BC2 -> 97.69 | AQ2: =BF2 -> 1/2 GAL | AS2: =BE2 -> N/A | AT2: RESUFLOR 3500 EPOXY QUICK PATCH (FAST) | AU2: 1/2 GAL | AV2: =AT2&AU2 -> RESUFLOR 3500 EPOXY QUICK PATCH (FAST)1/2 GAL | AW2: 97.69 | AY2: =_xlfn.CONCAT(AZ2:BB2) -> 3500 EPOXYN//A1/2 | AZ2: =MID(BD2,10,10) -> 3500 EPOXY | BA2: =LEFT(BE2,2)&RIGHT(BE2,2) -> N//A | BB2: =LEFT(BF2,3) -> 1/2 | BC2: =IFERROR(VLOOKUP(BD2&BF2,AV:AW,2,FALSE),0) -> 97.69 | BD2: RESUFLOR 3500 EPOXY QUICK PATCH (FAST) | BE2: N/A | BF2: 1/2 GAL | BG2: PATCH | BH2: GRAY | BI2: 2 GAL | BJ2: ACCELERA 4850 GROUT/TOPCOAT POLYASPARTIC | BK2: POLY | BL2: RESUPRIME 3477 EPOXY WATER PRIMER/SEALER | BM2: PRIMER | BN2: RESUTILE 4638 HS POLYURETHANE FLOOR ENAMEL | BO2: URETHANE
A3: SIKA | B3: =IFERROR(VLOOKUP(B$1,SIKA!$C:$D,2,FALSE),0) -> 0 | C3: =IFERROR(VLOOKUP(C$1,SIKA!$C:$D,2,FALSE),0) -> 0 | D3: =IFERROR(VLOOKUP(D$1,SIKA!$C:$D,2,FALSE),0) -> 0 | E3: =IFERROR(VLOOKUP(E$1,SIKA!$C:$D,2,FALSE),0) -> 0 | F3: =IFERROR(VLOOKUP(F$1,SIKA!$C:$D,2,FALSE),0) -> 0 | G3: =IFERROR(VLOOKUP(G$1,SIKA!$C:$D,2,FALSE),0) -> 0 | H3: =IFERROR(VLOOKUP(H$1,SIKA!$C:$D,2,FALSE),0) -> 0 | I3: =IFERROR(VLOOKUP(I$1,SIKA!$C:$D,2,FALSE),0) -> 0 | J3: =IFERROR(VLOOKUP(J$1,SIKA!$F:$H,3,FALSE),0) -> 0 | K3: =IFERROR(VLOOKUP(K$1,SIKA!$F:$H,3,FALSE),0) -> 0 | L3: =IFERROR(VLOOKUP(L$1,SIKA!$F:$H,3,FALSE),0) -> 0 | M3: =IFERROR(VLOOKUP(M$1,SIKA!$F:$H,3,FALSE),0) -> 0 | N3: =IFERROR(VLOOKUP(N$1,SIKA!$F:$H,3,FALSE),0) -> 0 | O3: =IFERROR(VLOOKUP(O$1,SIKA!$F:$H,3,FALSE),0) -> 0 | P3: =IFERROR(VLOOKUP(P$1,SIKA!$F:$H,3,FALSE),0) -> 0 | Q3: =IFERROR(VLOOKUP(Q$1,SIKA!$C:$D,2,FALSE),0) -> 0 | R3: =IFERROR(VLOOKUP(R$1,SIKA!$F:$H,3,FALSE),0) -> 0 | S3: =IFERROR(VLOOKUP(S$1,SIKA!$F:$H,3,FALSE),0) -> 0 | T3: =SUM(SIKA!N69:O71) -> 0 | U3: =VLOOKUP("CUSTOMER BID AMOUNT*",SIKA!$M:$Q,5,FALSE) -> 0 | V3: =IFERROR(VLOOKUP(V$1,SIKA!$P:$R,3,FALSE),0) -> 0 | W3: 600UV GA | X3: JS4C | Y3: 600UV Joint Filler Pigment | Z3: =Table1[[#This Row],[D:D]] -> 22 | AA3: Pack | AD3: RIO | AE3: 20 | AF3: =Table1[[#This Row],[C:C]]*1.1 -> 22 | AI3: =IFERROR(VLOOKUP(X3,#REF!,8,FALSE),0) -> 0 | AK3: MXN | AL3: #VALUE! | AM3: {=_FV(AL3,"Price")} -> 17.7247 | AN3: =PROD_ID_TABLE[[#This Row],[PROD ID]] -> M. URETHAN//A44 | AO3: =_xlfn.CONCAT(BD3:BF3) -> CEMLACK UM. URETHANE CEMENT PATCH 1:1:1N/A44 LBS | AP3: =BC3 -> 47.67 | AQ3: =BF3 -> 44 LBS | AS3: =BE3 -> N/A | AT3: RESUFLOR 3513 SCRATCH COAT MASTIC (THICK/SLOW) | AU3: 2 GAL | AV3: =AT3&AU3 -> RESUFLOR 3513 SCRATCH COAT MASTIC (THICK/SLOW)2 GAL | AW3: 104.75 | AY3: =_xlfn.CONCAT(AZ3:BB3) -> M. URETHAN//A44 | AZ3: =MID(BD3,10,10) -> M. URETHA | BA3: =LEFT(BE3,2)&RIGHT(BE3,2) -> N//A | BB3: =LEFT(BF3,3) -> 44 | BC3: =IFERROR(VLOOKUP(BD3&BF3,AV:AW,2,FALSE),0) -> 47.67 | BD3: CEMLACK UM. URETHANE CEMENT PATCH 1:1:1 | BE3: N/A | BF3: 44 LBS | BG3: PATCH | BH3: WHITE | BJ3: RESUDECK FLA CLEAR ALIPHATIC POLYASPARTIC TOPCOAT | BK3: POLY | BL3: RESUPRIME 3504 HIGH SOLID CLEAR PRIMER/SEALER | BM3: PRIMER | BN3: RESUTILE 4640 HTS 100 HS HIGH TRAFFIC URETHANE ENAMEL | BO3: URETHANE
A4: SW | B4: =IFERROR(VLOOKUP(B$1,SW!$C:$D,2,FALSE),0) -> 0 | C4: =IFERROR(VLOOKUP(C$1,SW!$C:$D,2,FALSE),0) -> 0 | D4: =IFERROR(VLOOKUP(D$1,SW!$C:$D,2,FALSE),0) -> 0 | E4: =IFERROR(VLOOKUP(E$1,SW!$C:$D,2,FALSE),0) -> 0 | F4: =IFERROR(VLOOKUP(F$1,SW!$C:$D,2,FALSE),0) -> 0 | G4: =IFERROR(VLOOKUP(G$1,SW!$C:$D,2,FALSE),0) -> 0 | H4: =IFERROR(VLOOKUP(H$1,SW!$C:$D,2,FALSE),0) -> 0 | I4: =IFERROR(VLOOKUP(I$1,SW!$C:$D,2,FALSE),0) -> 0 | J4: =IFERROR(VLOOKUP(J$1,SW!$F:$H,3,FALSE),0) -> 0 | K4: =IFERROR(VLOOKUP(K$1,SW!$F:$H,3,FALSE),0) -> 0 | L4: =IFERROR(VLOOKUP(L$1,SW!$F:$H,3,FALSE),0) -> 0 | M4: =IFERROR(VLOOKUP(M$1,SW!$F:$H,3,FALSE),0) -> 0 | N4: =IFERROR(VLOOKUP(N$1,SW!$F:$H,3,FALSE),0) -> 0 | O4: =IFERROR(VLOOKUP(O$1,SW!$F:$H,3,FALSE),0) -> 0 | P4: =IFERROR(VLOOKUP(P$1,SW!$F:$H,3,FALSE),0) -> 0 | Q4: =IFERROR(VLOOKUP(Q$1,SW!$C:$D,2,FALSE),0) -> 0 | R4: =IFERROR(VLOOKUP(R$1,SW!$F:$H,3,FALSE),0) -> 0 | S4: =IFERROR(VLOOKUP(S$1,SW!$F:$H,3,FALSE),0) -> 0 | T4: =SUM(SW!N92:O94) -> 0 | U4: =VLOOKUP("CUSTOMER BID AMOUNT*",SW!$M:$Q,5,FALSE) -> 0 | V4: =IFERROR(VLOOKUP(V$1,SW!$P:$R,3,FALSE),0) -> 0 | W4: 600UV CG | X4: JS4U | Y4: 600UV Joint Filler | Z4: =Table1[[#This Row],[D:D]] -> 125.4 | AA4: Box | AD4: RIO | AE4: 114 | AF4: =Table1[[#This Row],[C:C]]*1.1 -> 125.4 | AI4: =IFERROR(VLOOKUP(X4,#REF!,8,FALSE),0) -> 0 | AN4: =PROD_ID_TABLE[[#This Row],[PROD ID]] -> 3513 SCRATGRAY2 G | AO4: =_xlfn.CONCAT(BD4:BF4) -> RESUFLOR 3513 SCRATCH COAT MASTIC (THICK/SLOW)GRAY2 GAL | AP4: =BC4 -> 104.75 | AQ4: =BF4 -> 2 GAL | AS4: =BE4 -> GRAY | AT4: RESUPRIME 3477 EPOXY WATER PRIMER/SEALER | AU4: 3 GAL | AV4: =AT4&AU4 -> RESUPRIME 3477 EPOXY WATER PRIMER/SEALER3 GAL | AW4: 217.16 | AY4: =_xlfn.CONCAT(AZ4:BB4) -> 3513 SCRATGRAY2 G | AZ4: =MID(BD4,10,10) -> 3513 SCRAT | BA4: =LEFT(BE4,2)&RIGHT(BE4,2) -> GRAY | BB4: =LEFT(BF4,3) -> 2 G | BC4: =IFERROR(VLOOKUP(BD4&BF4,AV:AW,2,FALSE),0) -> 104.75 | BD4: RESUFLOR 3513 SCRATCH COAT MASTIC (THICK/SLOW) | BE4: GRAY | BF4: 2 GAL | BG4: PATCH | BH4: N/A | BJ4: ACCELERA EXT SMALL 1R:1H | BL4: RESUPRIME 3579 HIGH SOLID EPOXY PRIMER/BINDER | BM4: PRIMER | BN4: RESUTILE 4641 HPS 100 HS ALIPHATIC URETHANE TOPCOAT | BO4: URETHANE
X5: JS4U-CG | Y5: 600UV Joint Filler - Chateau Gray | Z5: =Table1[[#This Row],[D:D]] -> 125.4 | AA5: Box | AD5: RIO | AE5: 114 | AF5: =Table1[[#This Row],[C:C]]*1.1 -> 125.4 | AI5: =IFERROR(VLOOKUP(X5,#REF!,8,FALSE),0) -> 0 | AN5: =PROD_ID_TABLE[[#This Row],[PROD ID]] -> 3513 SCRATWHTE2 G | AO5: =_xlfn.CONCAT(BD5:BF5) -> RESUFLOR 3513 SCRATCH COAT MASTIC (THICK/SLOW)WHITE2 GAL | AP5: =BC5 -> 104.75 | AQ5: =BF5 -> 2 GAL | AS5: =BE5 -> WHITE | AT5: RESUPRIME 3477 EPOXY WATER PRIMER/SEALER | AU5: 15 GAL | AV5: =AT5&AU5 -> RESUPRIME 3477 EPOXY WATER PRIMER/SEALER15 GAL | AW5: 1034.58 | AY5: =_xlfn.CONCAT(AZ5:BB5) -> 3513 SCRATWHTE2 G | AZ5: =MID(BD5,10,10) -> 3513 SCRAT | BA5: =LEFT(BE5,2)&RIGHT(BE5,2) -> WHTE | BB5: =LEFT(BF5,3) -> 2 G | BC5: =IFERROR(VLOOKUP(BD5&BF5,AV:AW,2,FALSE),0) -> 104.75 | BD5: RESUFLOR 3513 SCRATCH COAT MASTIC (THICK/SLOW) | BE5: WHITE | BF5: 2 GAL | BG5: PATCH | BH5: PRIMER | BJ5: ACCELERA ONE RESIN (SEE MIX CHART) | BL5: RESUPRIME 3831 MVB MOISTURE EPOXY PRIMER | BM5: PRIMER | BN5: RESUTILE AQUA 4410 WB ALIPHATIC URETHANE - COLOR | BO5: URETHANE
A6: BLANK | B6: =IFERROR(VLOOKUP(B$1,BLANK!$M:$N,2,FALSE),0) -> 0 | C6: =IFERROR(VLOOKUP(C$1,BLANK!$M:$N,2,FALSE),0) -> 0 | D6: =IFERROR(VLOOKUP(D$1,BLANK!$M:$N,2,FALSE),0) -> 0 | E6: =IFERROR(VLOOKUP(E$1,BLANK!$M:$N,2,FALSE),0) -> 0 | F6: =IFERROR(VLOOKUP(F$1,BLANK!$M:$N,2,FALSE),0) -> 0 | G6: =IFERROR(VLOOKUP(G$1,BLANK!$M:$N,2,FALSE),0) -> 0 | H6: =IFERROR(VLOOKUP(H$1,BLANK!$M:$N,2,FALSE),0) -> 0 | I6: =IFERROR(VLOOKUP(I$1,BLANK!$M:$N,2,FALSE),0) -> 0 | J6: =IFERROR(VLOOKUP(J$1,BLANK!$P:$R,3,FALSE),0) -> 0 | K6: =IFERROR(VLOOKUP(K$1,BLANK!$P:$R,3,FALSE),0) -> 0 | L6: =IFERROR(VLOOKUP(L$1,BLANK!$P:$R,3,FALSE),0) -> 0 | M6: =IFERROR(VLOOKUP(M$1,BLANK!$P:$R,3,FALSE),0) -> 0 | N6: =IFERROR(VLOOKUP(N$1,BLANK!$P:$R,3,FALSE),0) -> 0 | O6: =IFERROR(VLOOKUP(O$1,BLANK!$P:$R,3,FALSE),0) -> 0 | P6: =IFERROR(VLOOKUP(P$1,BLANK!$P:$R,3,FALSE),0) -> 0 | Q6: =IFERROR(VLOOKUP(Q$1,BLANK!$M:$N,2,FALSE),0) -> 0 | R6: =IFERROR(VLOOKUP(R$1,BLANK!$P:$R,3,FALSE),0) -> 0 | S6: =IFERROR(VLOOKUP(S$1,BLANK!$P:$R,3,FALSE),0) -> 0 | T6: =VLOOKUP("TAX*",BLANK!$M:$Q,5,FALSE) -> 0 | U6: =VLOOKUP("CUSTOMER BID AMOUNT*",BLANK!$M:$Q,5,FALSE) -> 0 | V6: =IFERROR(VLOOKUP(V$1,BLANK!$P:$R,3,FALSE),0) -> 0 | X6: JS4U-GA | Y6: 600UV Joint Filler - Gray Area | Z6: =Table1[[#This Row],[D:D]] -> 125.4 | AA6: Box | AD6: RIO | AE6: 114 | AF6: =Table1[[#This Row],[C:C]]*1.1 -> 125.4 | AI6: =IFERROR(VLOOKUP(X6,#REF!,8,FALSE),0) -> 0 | AN6: =PROD_ID_TABLE[[#This Row],[PROD ID]] -> 3477 EPOXN//A3 G | AO6: =_xlfn.CONCAT(BD6:BF6) -> RESUPRIME 3477 EPOXY WATER PRIMER/SEALERN/A3 GAL | AP6: =BC6 -> 217.16 | AQ6: =BF6 -> 3 GAL | AS6: =BE6 -> N/A | AT6: RESUPRIME 3504 HIGH SOLID CLEAR PRIMER/SEALER | AU6: 2 GAL | AV6: =AT6&AU6 -> RESUPRIME 3504 HIGH SOLID CLEAR PRIMER/SEALER2 GAL | AW6: 168.31 | AY6: =_xlfn.CONCAT(AZ6:BB6) -> 3477 EPOXN//A3 G | AZ6: =MID(BD6,10,10) -> 3477 EPOX | BA6: =LEFT(BE6,2)&RIGHT(BE6,2) -> N//A | BB6: =LEFT(BF6,3) -> 3 G | BC6: =IFERROR(VLOOKUP(BD6&BF6,AV:AW,2,FALSE),0) -> 217.16 | BD6: RESUPRIME 3477 EPOXY WATER PRIMER/SEALER | BE6: N/A | BF6: 3 GAL | BG6: PRIMER | BH6: N/A | BJ6: ACCELERA ONE HARDENER (SEE MIX CHART) | BL6: RESUPRIME 5531 OIL STOP PRIMER | BM6: PRIMER | BN6: RESUTILE AQUA 4411 WB ALIPHATIC URETHANE - CLEAR | BO6: URETHANE
A7: POLISH | X7: R-CSB-25 | Y7: RIO Sandy Beige Colorant | Z7: =Table1[[#This Row],[D:D]] -> 440 | AA7: 25 Pint | AD7: RIO | AE7: 400 | AF7: =Table1[[#This Row],[C:C]]*1.1 -> 440 | AI7: =IFERROR(VLOOKUP(X7,#REF!,8,FALSE),0) -> 0 | AN7: =PROD_ID_TABLE[[#This Row],[PROD ID]] -> 3477 EPOXN//A15 | AO7: =_xlfn.CONCAT(BD7:BF7) -> RESUPRIME 3477 EPOXY WATER PRIMER/SEALERN/A15 GAL | AP7: =BC7 -> 1034.58 | AQ7: =BF7 -> 15 GAL | AS7: =BE7 -> N/A | AT7: RESUPRIME 3504 HIGH SOLID CLEAR PRIMER/SEALER | AU7: 10 GAL | AV7: =AT7&AU7 -> RESUPRIME 3504 HIGH SOLID CLEAR PRIMER/SEALER10 GAL | AW7: 800.36 | AY7: =_xlfn.CONCAT(AZ7:BB7) -> 3477 EPOXN//A15 | AZ7: =MID(BD7,10,10) -> 3477 EPOX | BA7: =LEFT(BE7,2)&RIGHT(BE7,2) -> N//A | BB7: =LEFT(BF7,3) -> 15 | BC7: =IFERROR(VLOOKUP(BD7&BF7,AV:AW,2,FALSE),0) -> 1034.58 | BD7: RESUPRIME 3477 EPOXY WATER PRIMER/SEALER | BE7: N/A | BF7: 15 GAL | BG7: PRIMER | BH7: CLEAR | BJ7: ACCELERA 5 66% SOLIDS 1:1 | BL7: RESUPRIME MVP EPOXY PRIMER | BM7: PRIMER
X8: JS4U-SG | Y8: 600UV Joint Filler - Standard Gray | Z8: =Table1[[#This Row],[D:D]] -> 125.4 | AA8: Box | AD8: RIO | AE8: 114 | AF8: =Table1[[#This Row],[C:C]]*1.1 -> 125.4 | AI8: =IFERROR(VLOOKUP(X8,#REF!,8,FALSE),0) -> 0 | AN8: =PROD_ID_TABLE[[#This Row],[PROD ID]] -> 3504 HIGHCLAR2 G | AO8: =_xlfn.CONCAT(BD8:BF8) -> RESUPRIME 3504 HIGH SOLID CLEAR PRIMER/SEALERCLEAR2 GAL | AP8: =BC8 -> 168.31 | AQ8: =BF8 -> 2 GAL | AS8: =BE8 -> CLEAR | AT8: RESUPRIME 3579 HIGH SOLID EPOXY PRIMER/BINDER | AU8: 3 GAL | AV8: =AT8&AU8 -> RESUPRIME 3579 HIGH SOLID EPOXY PRIMER/BINDER3 GAL | AW8: 187.14 | AY8: =_xlfn.CONCAT(AZ8:BB8) -> 3504 HIGHCLAR2 G | AZ8: =MID(BD8,10,10) -> 3504 HIGH | BA8: =LEFT(BE8,2)&RIGHT(BE8,2) -> CLAR | BB8: =LEFT(BF8,3) -> 2 G | BC8: =IFERROR(VLOOKUP(BD8&BF8,AV:AW,2,FALSE),0) -> 168.31 | BD8: RESUPRIME 3504 HIGH SOLID CLEAR PRIMER/SEALER | BE8: CLEAR | BF8: 2 GAL | BG8: PRIMER | BH8: GRAY | BM8: PRIMER
B9: =SUM(B2:B8) -> 0 | C9: =SUM(C2:C8) -> 0 | D9: =SUM(D2:D8) -> 0 | E9: =SUM(E2:E8) -> 0 | F9: =SUM(F2:F8) -> 0 | G9: =SUM(G2:G8) -> 0 | H9: =SUM(H2:H8) -> 0 | I9: =SUM(I2:I8) -> 0 | ... V9: =SUM(V2:V8) -> 0 | X9: R-EMP-15 | Y9: RIO Coat EMP | Z9: =Table1[[#This Row],[D:D]] -> 973.5 | AA9: 15 gal | AD9: RIO | AE9: 885 | AF9: =Table1[[#This Row],[C:C]]*1.1 -> 973.5 | AI9: =IFERROR(VLOOKUP(X9,#REF!,8,FALSE),0) -> 0 | AN9: =PROD_ID_TABLE[[#This Row],[PROD ID]] -> 3504 HIGHGRAY2 G | AO9: =_xlfn.CONCAT(BD9:BF9) -> RESUPRIME 3504 HIGH SOLID CLEAR PRIMER/SEALERGRAY2 GAL | AP9: =BC9 -> 168.31 | AQ9: =BF9 -> 2 GAL | AS9: =BE9 -> GRAY | AT9: RESUPRIME 3579 HIGH SOLID EPOXY PRIMER/BINDER | AU9: 15 GAL | AV9: =AT9&AU9 -> RESUPRIME 3579 HIGH SOLID EPOXY PRIMER/BINDER15 GAL | AW9: 873.92 | AY9: =_xlfn.CONCAT(AZ9:BB9) -> 3504 HIGHGRAY2 G | AZ9: =MID(BD9,10,10) -> 3504 HIGH | BA9: =LEFT(BE9,2)&RIGHT(BE9,2) -> GRAY | BB9: =LEFT(BF9,3) -> 2 G | BC9: =IFERROR(VLOOKUP(BD9&BF9,AV:AW,2,FALSE),0) -> 168.31 | BD9: RESUPRIME 3504 HIGH SOLID CLEAR PRIMER/SEALER | BE9: GRAY | BF9: 2 GAL | BG9: PRIMER | BH9: WHITE
N10: 5-100 RETURN FREIGHT | X10: R-EMP-3 | Y10: RIO Coat EMP | Z10: =Table1[[#This Row],[D:D]] -> 194.7 | AA10: 3 gal kit | AD10: RIO | AE10: 177 | AF10: =Table1[[#This Row],[C:C]]*1.1 -> 194.7 | AI10: =IFERROR(VLOOKUP(X10,#REF!,8,FALSE),0) -> 0 | AN10: =PROD_ID_TABLE[[#This Row],[PROD ID]] -> 3504 HIGHWHTE2 G | AO10: =_xlfn.CONCAT(BD10:BF10) -> RESUPRIME 3504 HIGH SOLID CLEAR PRIMER/SEALERWHITE2 GAL | AP10: =BC10 -> 168.31 | AQ10: =BF10 -> 2 GAL | AS10: =BE10 -> WHITE | AT10: RESUPRIME 3831 MVB MOISTURE EPOXY PRIMER | AU10: 2 GAL | AV10: =AT10&AU10 -> RESUPRIME 3831 MVB MOISTURE EPOXY PRIMER2 GAL | AW10: 135.36 | AY10: =_xlfn.CONCAT(AZ10:BB10) -> 3504 HIGHWHTE2 G | AZ10: =MID(BD10,10,10) -> 3504 HIGH | BA10: =LEFT(BE10,2)&RIGHT(BE10,2) -> WHTE | BB10: =LEFT(BF10,3) -> 2 G | BC10: =IFERROR(VLOOKUP(BD10&BF10,AV:AW,2,FALSE),0) -> 168.31 | BD10: RESUPRIME 3504 HIGH SOLID CLEAR PRIMER/SEALER | BE10: WHITE | BF10: 2 GAL | BG10: PRIMER | BH10: BLACK
X11: NP-1 | Y11: NP-1 Tubes | Z11: =Table1[[#This Row],[D:D]] -> 9.174 | AA11: Tube | AC11: Aluminum Gray | AD11: RIO | AE11: 8.34 | AF11: =Table1[[#This Row],[C:C]]*1.1 -> 9.174 | AI11: =IFERROR(VLOOKUP(X11,#REF!,8,FALSE),0) -> 0 | AN11: =PROD_ID_TABLE[[#This Row],[PROD ID]] -> 3504 HIGHCLAR10 | AO11: =_xlfn.CONCAT(BD11:BF11) -> RESUPRIME 3504 HIGH SOLID CLEAR PRIMER/SEALERCLEAR10 GAL | AP11: =BC11 -> 800.36 | AQ11: =BF11 -> 10 GAL | AS11: =BE11 -> CLEAR | AT11: RESUPRIME 3831 MVB MOISTURE EPOXY PRIMER | AU11: 10 GAL | AV11: =AT11&AU11 -> RESUPRIME 3831 MVB MOISTURE EPOXY PRIMER10 GAL | AW11: 641.47 | AY11: =_xlfn.CONCAT(AZ11:BB11) -> 3504 HIGHCLAR10 | AZ11: =MID(BD11,10,10) -> 3504 HIGH | BA11: =LEFT(BE11,2)&RIGHT(BE11,2) -> CLAR | BB11: =LEFT(BF11,3) -> 10 | BC11: =IFERROR(VLOOKUP(BD11&BF11,AV:AW,2,FALSE),0) -> 800.36 | BD11: RESUPRIME 3504 HIGH SOLID CLEAR PRIMER/SEALER | BE11: CLEAR | BF11: 10 GAL | BG11: PRIMER | BH11: TILE RED
X12: R-A60-1 | Y12: #60 Grit Clear White Alu Oxide | Z12: =Table1[[#This Row],[D:D]] -> 198 | AA12: Bag | AD12: RIO | AE12: 180 | AF12: =Table1[[#This Row],[C:C]]*1.1 -> 198 | AI12: =IFERROR(VLOOKUP(X12,#REF!,8,FALSE),0) -> 0 | AN12: =PROD_ID_TABLE[[#This Row],[PROD ID]] -> 3504 HIGHGRAY10 | AO12: =_xlfn.CONCAT(BD12:BF12) -> RESUPRIME 3504 HIGH SOLID CLEAR PRIMER/SEALERGRAY10 GAL | AP12: =BC12 -> 800.36 | AQ12: =BF12 -> 10 GAL | AS12: =BE12 -> GRAY | AT12: RESUPRIME MVP EPOXY PRIMER | AU12: 3 GAL | AV12: =AT12&AU12 -> RESUPRIME MVP EPOXY PRIMER3 GAL | AW12: 421.2 | AY12: =_xlfn.CONCAT(AZ12:BB12) -> 3504 HIGHGRAY10 | AZ12: =MID(BD12,10,10) -> 3504 HIGH | BA12: =LEFT(BE12,2)&RIGHT(BE12,2) -> GRAY | BB12: =LEFT(BF12,3) -> 10 | BC12: =IFERROR(VLOOKUP(BD12&BF12,AV:AW,2,FALSE),0) -> 800.36 | BD12: RESUPRIME 3504 HIGH SOLID CLEAR PRIMER/SEALER | BE12: GRAY | BF12: 10 GAL | BG12: PRIMER | BH12: CONCRETE GRAY
A13: DESCRIPTION - EPOXY | B13: DESCRIPTION - POLY | C13: DESCRIPTION - AGG | D13: DESCRIPTION - MMA | E13: DESCRIPTION - JOINT | F13: DESCRIPTION - CRETE | G13: DESCRIPTION - COLOR | I13: PROD ID | J13: LOOKUP | K13: DESCRIPTION | L13: COLOR | M13: UOM | X13: R-CBG-1 | Y13: RIO Battleship Gray | Z13: =Table1[[#This Row],[D:D]] -> 28.05 | AA13: Pint | AD13: RIO | AE13: 25.5 | AF13: =Table1[[#This Row],[C:C]]*1.1 -> 28.05 | AI13: =IFERROR(VLOOKUP(X13,#REF!,8,FALSE),0) -> 0 | AN13: =PROD_ID_TABLE[[#This Row],[PROD ID]] -> 3504 HIGHWHTE10 | AO13: =_xlfn.CONCAT(BD13:BF13) -> RESUPRIME 3504 HIGH SOLID CLEAR PRIMER/SEALERWHITE10 GAL | AP13: =BC13 -> 800.36 | AQ13: =BF13 -> 10 GAL | AS13: =BE13 -> WHITE | AT13: RESUPRIME MVP EPOXY PRIMER | AU13: 15 GAL | AV13: =AT13&AU13 -> RESUPRIME MVP EPOXY PRIMER15 GAL | AW13: 1787.4 | AY13: =_xlfn.CONCAT(AZ13:BB13) -> 3504 HIGHWHTE10 | AZ13: =MID(BD13,10,10) -> 3504 HIGH | BA13: =LEFT(BE13,2)&RIGHT(BE13,2) -> WHTE | BB13: =LEFT(BF13,3) -> 10 | BC13: =IFERROR(VLOOKUP(BD13&BF13,AV:AW,2,FALSE),0) -> 800.36 | BD13: RESUPRIME 3504 HIGH SOLID CLEAR PRIMER/SEALER | BE13: WHITE | BF13: 10 GAL | BG13: PRIMER
A14: SGC DECK BASE COAT 308 | B14: SGC POLYASPARTIC (100% Solid) | C14: FLAKE | D14: SGC SHIELD BODY COAT | E14: NP-1 TUBES (30 TUBE/CASE) | F14: SGC CRETE PART A | G14: POLYASPARTIC COLORANT | I14: S-DEB-5 | J14: =_xlfn.CONCAT(K14:M14) -> SGC DECK BASE COAT 308N/A5 GAL | K14: SGC DECK BASE COAT 308 | L14: N/A | M14: 5 GAL | X14: R-CBG-25 | Y14: RIO Battleship Gray | Z14: =Table1[[#This Row],[D:D]] -> 514.25 | AA14: 25 Pint | AD14: RIO | AE14: 467.5 | AF14: =Table1[[#This Row],[C:C]]*1.1 -> 514.25 | AI14: =IFERROR(VLOOKUP(X14,#REF!,8,FALSE),0) -> 0 | AN14: =PROD_ID_TABLE[[#This Row],[PROD ID]] -> 3579 HIGHCOAY3 G | AO14: =_xlfn.CONCAT(BD14:BF14) -> RESUPRIME 3579 HIGH SOLID EPOXY PRIMER/BINDERCONCRETE GRAY3 GAL | AP14: =BC14 -> 187.14 | AQ14: =BF14 -> 3 GAL | AS14: =BE14 -> CONCRETE GRAY | AT14: RESUPRIME 5531 OIL STOP PRIMER | AU14: 1 QT | AV14: =AT14&AU14 -> RESUPRIME 5531 OIL STOP PRIMER1 QT | AW14: 48.26 | AY14: =_xlfn.CONCAT(AZ14:BB14) -> 3579 HIGHCOAY3 G | AZ14: =MID(BD14,10,10) -> 3579 HIGH | BA14: =LEFT(BE14,2)&RIGHT(BE14,2) -> COAY | BB14: =LEFT(BF14,3) -> 3 G | BC14: =IFERROR(VLOOKUP(BD14&BF14,AV:AW,2,FALSE),0) -> 187.14 | BD14: RESUPRIME 3579 HIGH SOLID EPOXY PRIMER/BINDER | BE14: CONCRETE GRAY | BF14: 3 GAL | BG14: PRIMER | BH14: 2 GAL
A15: SGC SHIELD FLEX | C15: QUARTZ | D15: SGC SHIELD TOP COAT | E15: 600 UV (SSP JS-600 ALIPHATIC POLYUREA) | F15: SGC CRETE PART B | G15: CRETE COLORANT | I15: S-GPR-3 | J15: =_xlfn.CONCAT(K15:M15) -> SGC SHIELD FLEXN/A3 GAL | K15: SGC SHIELD FLEX | L15: N/A | M15: 3 GAL | X15: R-CBK-1 | Y15: RIO Black Colorant | Z15: =Table1[[#This Row],[D:D]] -> 30.855 | AA15: Pint | AD15: RIO | AE15: 28.05 | AF15: =Table1[[#This Row],[C:C]]*1.1 -> 30.855 | AI15: =IFERROR(VLOOKUP(X15,#REF!,8,FALSE),0) -> 0 | AN15: =PROD_ID_TABLE[[#This Row],[PROD ID]] -> 3579 HIGHWHTE3 G | AO15: =_xlfn.CONCAT(BD15:BF15) -> RESUPRIME 3579 HIGH SOLID EPOXY PRIMER/BINDERWHITE3 GAL | AP15: =BC15 -> 187.14 | AQ15: =BF15 -> 3 GAL | AS15: =BE15 -> WHITE | AT15: RESUPRIME 5531 OIL STOP PRIMER | AU15: 5 GAL | AV15: =AT15&AU15 -> RESUPRIME 5531 OIL STOP PRIMER5 GAL | AW15: 123 | AY15: =_xlfn.CONCAT(AZ15:BB15) -> 3579 HIGHWHTE3 G | AZ15: =MID(BD15,10,10) -> 3579 HIGH | BA15: =LEFT(BE15,2)&RIGHT(BE15,2) -> WHTE | BB15: =LEFT(BF15,3) -> 3 G | BC15: =IFERROR(VLOOKUP(BD15&BF15,AV:AW,2,FALSE),0) -> 187.14 | BD15: RESUPRIME 3579 HIGH SOLID EPOXY PRIMER/BINDER | BE15: WHITE | BF15: 3 GAL | BG15: PRIMER | BH15: 10 GAL
A16: FIBERGLASS TAPE | C16: TROWEL QUARTZ | D16: SGC BPO CATALYST | E16: RS88 (12 TUBES / CASE) | F16: SL - PART C | G16: CRETE COLORANT - LARGE | I16: FIBERTAPE | J16: =_xlfn.CONCAT(K16:M16) -> FIBERGLASS TAPEN/AROLL | K16: FIBERGLASS TAPE | L16: N/A | M16: ROLL | X16: R-CCB-1 | Y16: CB - Part C | Z16: =Table1[[#This Row],[D:D]] -> 18.359 | AA16: 28lb bag | AC16: PIGMENTED | AD16: RIO | AE16: 16.69 | AF16: =Table1[[#This Row],[C:C]]*1.1 -> 18.359 | AI16: =IFERROR(VLOOKUP(X16,#REF!,8,FALSE),0) -> 0 | AN16: =PROD_ID_TABLE[[#This Row],[PROD ID]] -> 3579 HIGHBLCK3 G | AO16: =_xlfn.CONCAT(BD16:BF16) -> RESUPRIME 3579 HIGH SOLID EPOXY PRIMER/BINDERBLACK3 GAL | AP16: =BC16 -> 187.14 | AQ16: =BF16 -> 3 GAL | AS16: =BE16 -> BLACK | AT16: POLY-CRETE TF PLUS PRIMER/TOPCOAT | AU16: KIT | AV16: =AT16&AU16 -> POLY-CRETE TF PLUS PRIMER/TOPCOATKIT | AW16: 53.55 | AY16: =_xlfn.CONCAT(AZ16:BB16) -> 3579 HIGHBLCK3 G | AZ16: =MID(BD16,10,10) -> 3579 HIGH | BA16: =LEFT(BE16,2)&RIGHT(BE16,2) -> BLCK | BB16: =LEFT(BF16,3) -> 3 G | BC16: =IFERROR(VLOOKUP(BD16&BF16,AV:AW,2,FALSE),0) -> 187.14 | BD16: RESUPRIME 3579 HIGH SOLID EPOXY PRIMER/BINDER | BE16: BLACK | BF16: 3 GAL | BG16: PRIMER | BH16: 3 GAL
A17: RIO COAT EPT | C17: ALUMINUM OXIDE | D17: SGC COAT MMA CLEANER | E17: RS65 (12 TUBES / CASE) | F17: SF - PART C | I17: R-EPT-3 | J17: =_xlfn.CONCAT(K17:M17) -> RIO COAT EPTN/A3 GAL | K17: RIO COAT EPT | L17: N/A | M17: 3 GAL | X17: R-CMG-1 | Y17: RIO Medium Gray Colorant | Z17: =Table1[[#This Row],[D:D]] -> 28.05 | AA17: Pint | AD17: RIO | AE17: 25.5 | AF17: =Table1[[#This Row],[C:C]]*1.1 -> 28.05 | AI17: =IFERROR(VLOOKUP(X17,#REF!,8,FALSE),0) -> 0 | AN17: =PROD_ID_TABLE[[#This Row],[PROD ID]] -> 3579 HIGHTIED3 G | AO17: =_xlfn.CONCAT(BD17:BF17) -> RESUPRIME 3579 HIGH SOLID EPOXY PRIMER/BINDERTILE RED3 GAL | AP17: =BC17 -> 187.14 | AQ17: =BF17 -> 3 GAL | AS17: =BE17 -> TILE RED | AT17: POLY-CRETE TF PLUS PRIMER/TOPCOAT | AU17: KIT | AV17: =AT17&AU17 -> POLY-CRETE TF PLUS PRIMER/TOPCOATKIT | AW17: 190.67 | AY17: =_xlfn.CONCAT(AZ17:BB17) -> 3579 HIGHTIED3 G | AZ17: =MID(BD17,10,10) -> 3579 HIGH | BA17: =LEFT(BE17,2)&RIGHT(BE17,2) -> TIED | BB17: =LEFT(BF17,3) -> 3 G | BC17: =IFERROR(VLOOKUP(BD17&BF17,AV:AW,2,FALSE),0) -> 187.14 | BD17: RESUPRIME 3579 HIGH SOLID EPOXY PRIMER/BINDER | BE17: TILE RED | BF17: 3 GAL | BG17: PRIMER | BH17: 15 GAL | BJ17: RESUFLOR 3500 EPOXY QUICK PATCH (FAST) | BK17: PATCH | BL17: CRYLAFLOR P-101 PRIMER | BM17: MMA | BN17: RESUFLOR 3725 STATIC CONTROL EPOXY | BO17: EPOXY
A18: ROADWARE 10 MIN CONCRETE MENDER | C18: RIO TROWEL CLAD SAND | D18: SGC MMA PRIMER | F18: CB - PART C | I18: R-EPT-15 | J18: =_xlfn.CONCAT(K18:M18) -> RIO COAT EPTN/A15 GAL | K18: RIO COAT EPT | L18: N/A | M18: 15 GAL | X18: R-CMG-25 | Y18: RIO Medium Gray Colorant | Z18: =Table1[[#This Row],[D:D]] -> 440 | AA18: 25 Pint | AD18: RIO | AE18: 400 | AF18: =Table1[[#This Row],[C:C]]*1.1 -> 440 | AI18: =IFERROR(VLOOKUP(X18,#REF!,8,FALSE),0) -> 0 | AN18: =PROD_ID_TABLE[[#This Row],[PROD ID]] -> 3579 HIGHCOAY15 | AO18: =_xlfn.CONCAT(BD18:BF18) -> RESUPRIME 3579 HIGH SOLID EPOXY PRIMER/BINDERCONCRETE GRAY15 GAL | AP18: =BC18 -> 873.92 | AQ18: =BF18 -> 15 GAL | AS18: =BE18 -> CONCRETE GRAY | AT18: POLY-CRETE SL HS SELF LEVELING URETHANE | AU18: KIT | AV18: =AT18&AU18 -> POLY-CRETE SL HS SELF LEVELING URETHANEKIT | AW18: 102.4 | AY18: =_xlfn.CONCAT(AZ18:BB18) -> 3579 HIGHCOAY15 | AZ18: =MID(BD18,10,10) -> 3579 HIGH | BA18: =LEFT(BE18,2)&RIGHT(BE18,2) -> COAY | BB18: =LEFT(BF18,3) -> 15 | BC18: =IFERROR(VLOOKUP(BD18&BF18,AV:AW,2,FALSE),0) -> 873.92 | BD18: RESUPRIME 3579 HIGH SOLID EPOXY PRIMER/BINDER | BE18: CONCRETE GRAY | BF18: 15 GAL | BG18: PRIMER | BH18: 1 QT | BJ18: RESUFLOR 3513 SCRATCH COAT MASTIC (THICK/SLOW) | BK18: PATCH | BL18: CRYLAFLOR G-201 BINDER | BM18: MMA | BN18: RESUFLOR 3741 CHEMICAL RESISTANT NOVOLAC | BO18: EPOXY
A19: RIO COAT EMP | D19: RIO MMA BONDING ADDITIVE | F19: TC - PART C | I19: ROAD10600 | J19: =_xlfn.CONCAT(K19:M19) -> ROADWARE 10 MIN CONCRETE MENDERN/A600ML | K19: ROADWARE 10 MIN CONCRETE MENDER | L19: N/A | M19: 600ML | X19: R-CRR-1 | Y19: RIO Rotunda Red Colorant | Z19: =Table1[[#This Row],[D:D]] -> 33 | AA19: Pint | AD19: RIO | AE19: 30 | AF19: =Table1[[#This Row],[C:C]]*1.1 -> 33 | AI19: =IFERROR(VLOOKUP(X19,#REF!,8,FALSE),0) -> 0 | AN19: =PROD_ID_TABLE[[#This Row],[PROD ID]] -> 3579 HIGHWHTE15 | AO19: =_xlfn.CONCAT(BD19:BF19) -> RESUPRIME 3579 HIGH SOLID EPOXY PRIMER/BINDERWHITE15 GAL | AP19: =BC19 -> 873.92 | AQ19: =BF19 -> 15 GAL | AS19: =BE19 -> WHITE | AT19: POLY-CRETE MD HS URETHANE CONCRETE COATING | AU19: KIT | AV19: =AT19&AU19 -> POLY-CRETE MD HS URETHANE CONCRETE COATINGKIT | AW19: 116.52 | AY19: =_xlfn.CONCAT(AZ19:BB19) -> 3579 HIGHWHTE15 | AZ19: =MID(BD19,10,10) -> 3579 HIGH | BA19: =LEFT(BE19,2)&RIGHT(BE19,2) -> WHTE | BB19: =LEFT(BF19,3) -> 15 | BC19: =IFERROR(VLOOKUP(BD19&BF19,AV:AW,2,FALSE),0) -> 873.92 | BD19: RESUPRIME 3579 HIGH SOLID EPOXY PRIMER/BINDER | BE19: WHITE | BF19: 15 GAL | BG19: PRIMER | BH19: 5 GAL | BJ19: CEMLACK UM. URETHANE CEMENT PATCH 1:1:1 | BK19: PATCH | BL19: CRYLAFLOR T-301 TOPCOAT | BM19: MMA | BN19: RESUFLOR 3746 HIGH PERFORMANCE EPOXY | BO19: EPOXY
F20: SGC SPEED | I20: S-SPS-2.5 | J20: =_xlfn.CONCAT(K20:M20) -> SGC POLYASPARTIC (100% Solid)N/A2.5 GAL | K20: SGC POLYASPARTIC (100% Solid) | L20: N/A | M20: 2.5 GAL | X20: R-CSB-1 | Y20: RIO Sandy Beige Colorant | Z20: =Table1[[#This Row],[D:D]] -> 28.05 | AA20: Pint | AD20: RIO | AE20: 25.5 | AF20: =Table1[[#This Row],[C:C]]*1.1 -> 28.05 | AI20: =IFERROR(VLOOKUP(X20,#REF!,8,FALSE),0) -> 0 | AN20: =PROD_ID_TABLE[[#This Row],[PROD ID]] -> 3579 HIGHBLCK15 | AO20: =_xlfn.CONCAT(BD20:BF20) -> RESUPRIME 3579 HIGH SOLID EPOXY PRIMER/BINDERBLACK15 GAL | AP20: =BC20 -> 873.92 | AQ20: =BF20 -> 15 GAL | AS20: =BE20 -> BLACK | AT20: POLY-CRETE TF PLUS COVE VERTICAL APPLICATIONS | AU20: KIT | AV20: =AT20&AU20 -> POLY-CRETE TF PLUS COVE VERTICAL APPLICATIONSKIT | AW20: 31.8 | AY20: =_xlfn.CONCAT(AZ20:BB20) -> 3579 HIGHBLCK15 | AZ20: =MID(BD20,10,10) -> 3579 HIGH | BA20: =LEFT(BE20,2)&RIGHT(BE20,2) -> BLCK | BB20: =LEFT(BF20,3) -> 15 | BC20: =IFERROR(VLOOKUP(BD20&BF20,AV:AW,2,FALSE),0) -> 873.92 | BD20: RESUPRIME 3579 HIGH SOLID EPOXY PRIMER/BINDER | BE20: BLACK | BF20: 15 GAL | BG20: PRIMER | BJ20: HPF UNIVERSAL COLORANT | BK20: PATCH | BL20: CRYLAFLOR T-303 FLEXIBLE TOPCOAT | BM20: MMA | BN20: RESUFLOR 3760 MPE MULTI-PURPOSE EPOXY | BO20: EPOXY
I21: S-SPS-25 | J21: =_xlfn.CONCAT(K21:M21) -> SGC POLYASPARTIC (100% Solid)N/A25 GAL | K21: SGC POLYASPARTIC (100% Solid) | L21: N/A | M21: 25 GAL | X21: R-CSF-1 | Y21: SF - Part C | Z21: =Table1[[#This Row],[D:D]] -> 11.825 | AA21: 35lb bag | AD21: RIO | AE21: 10.75 | AF21: =Table1[[#This Row],[C:C]]*1.1 -> 11.825 | AI21: =IFERROR(VLOOKUP(X21,#REF!,8,FALSE),0) -> 0 | AN21: =PROD_ID_TABLE[[#This Row],[PROD ID]] -> 3831 MVB N//A2 G | AO21: =_xlfn.CONCAT(BD21:BF21) -> RESUPRIME 3831 MVB MOISTURE EPOXY PRIMERN/A2 GAL | AP21: =BC21 -> 135.36 | AQ21: =BF21 -> 2 GAL | AS21: =BE21 -> N/A | AT21: POLY-CRETE HF HS URETHANE CONCRETE COATING | AU21: KIT | AV21: =AT21&AU21 -> POLY-CRETE HF HS URETHANE CONCRETE COATINGKIT | AW21: 79.45 | AY21: =_xlfn.CONCAT(AZ21:BB21) -> 3831 MVB N//A2 G | AZ21: =MID(BD21,10,10) -> 3831 MVB | BA21: =LEFT(BE21,2)&RIGHT(BE21,2) -> N//A | BB21: =LEFT(BF21,3) -> 2 G | BC21: =IFERROR(VLOOKUP(BD21&BF21,AV:AW,2,FALSE),0) -> 135.36 | BD21: RESUPRIME 3831 MVB MOISTURE EPOXY PRIMER | BE21: N/A | BF21: 2 GAL | BG21: PRIMER | BL21: CRYLAFLOR COVE | BM21: MMA | BN21: RESUFLOR AQUA 3460 WB EPOXY PRIMER, BINDER, TOPCOAT | BO21: EPOXY
I22: S-QBS-1 | J22: =_xlfn.CONCAT(K22:M22) -> FLAKEASH40LB | K22: FLAKE | L22: ASH | M22: 40LB | X22: R-CSL-1 | Y22: SL - Part C | Z22: =Table1[[#This Row],[D:D]] -> 8.338 | AA22: 20lb bag | AD22: RIO | AE22: 7.58 | AF22: =Table1[[#This Row],[C:C]]*1.1 -> 8.338 | AI22: =IFERROR(VLOOKUP(X22,#REF!,8,FALSE),0) -> 0 | AN22: =PROD_ID_TABLE[[#This Row],[PROD ID]] -> 3831 MVB N//A10 | AO22: =_xlfn.CONCAT(BD22:BF22) -> RESUPRIME 3831 MVB MOISTURE EPOXY PRIMERN/A10 GAL | AP22: =BC22 -> 641.47 | AQ22: =BF22 -> 10 GAL | AS22: =BE22 -> N/A | AT22: POLY-CRETE COLOR-FAST | AU22: KIT | AV22: =AT22&AU22 -> POLY-CRETE COLOR-FASTKIT | AW22: 154.78 | AY22: =_xlfn.CONCAT(AZ22:BB22) -> 3831 MVB N//A10 | AZ22: =MID(BD22,10,10) -> 3831 MVB | BA22: =LEFT(BE22,2)&RIGHT(BE22,2) -> N//A | BB22: =LEFT(BF22,3) -> 10 | BC22: =IFERROR(VLOOKUP(BD22&BF22,AV:AW,2,FALSE),0) -> 641.47 | BD22: RESUPRIME 3831 MVB MOISTURE EPOXY PRIMER | BE22: N/A | BF22: 10 GAL | BG22: PRIMER | BL22: CRYLAFLOR CURE (BPO) | BM22: MMA | BN22: RESUFLOR AQUA 3461 HIGH SOLIDS WB EPOXY GROUT/TOPCOAT | BO22: EPOXY
I23: S-QMT-1 | J23: =_xlfn.CONCAT(K23:M23) -> QUARTZMALT50LB | K23: QUARTZ | L23: MALT | M23: 50LB | X23: R-CTC-1 | Y23: TC - Part C | Z23: =Table1[[#This Row],[D:D]] -> 11.22 | AA23: 6.5 lb bag | AC23: PIGMENTED | AD23: RIO | AE23: 10.2 | AF23: =Table1[[#This Row],[C:C]]*1.1 -> 11.22 | AI23: =IFERROR(VLOOKUP(X23,#REF!,8,FALSE),0) -> 0 | AN23: =PROD_ID_TABLE[[#This Row],[PROD ID]] -> MVP EPOXYN//A3 G | AO23: =_xlfn.CONCAT(BD23:BF23) -> RESUPRIME MVP EPOXY PRIMERN/A3 GAL | AP23: =BC23 -> 421.2 | AQ23: =BF23 -> 3 GAL | AS23: =BE23 -> N/A | AT23: POLY-CRETE COLOR-FAST | AU23: KIT | AV23: =AT23&AU23 -> POLY-CRETE COLOR-FASTKIT | AW23: 264.24 | AY23: =_xlfn.CONCAT(AZ23:BB23) -> MVP EPOXYN//A3 G | AZ23: =MID(BD23,10,10) -> MVP EPOXY | BA23: =LEFT(BE23,2)&RIGHT(BE23,2) -> N//A | BB23: =LEFT(BF23,3) -> 3 G | BC23: =IFERROR(VLOOKUP(BD23&BF23,AV:AW,2,FALSE),0) -> 421.2 | BD23: RESUPRIME MVP EPOXY PRIMER | BE23: N/A | BF23: 3 GAL | BG23: PRIMER | BI23: {=IF(B3="","",IF(B3=P!BL3,P!BE$8:BE$10,IF(B3=P!BL$4,P!BE$14:BE$17,P!BE$6)))} -> N/A | BL23: CRYLAFLOR COLOR - BACKGROUND ONLY | BM23: MMA | BN23: RESUTILE 4638 HS POLYURETHANE FLOOR ENAMEL
I24: S-QSM-1 | J24: =_xlfn.CONCAT(K24:M24) -> QUARTZGRAY50LB | K24: QUARTZ | L24: GRAY | M24: 50LB | X24: R-CTR-1 | Y24: RIO Tile Red Colorant | Z24: =Table1[[#This Row],[D:D]] -> 28.05 | AA24: Pint | AD24: RIO | AE24: 25.5 | AF24: =Table1[[#This Row],[C:C]]*1.1 -> 28.05 | AI24: =IFERROR(VLOOKUP(X24,#REF!,8,FALSE),0) -> 0 | AN24: =PROD_ID_TABLE[[#This Row],[PROD ID]] -> MVP EPOXYN//A15 | AO24: =_xlfn.CONCAT(BD24:BF24) -> RESUPRIME MVP EPOXY PRIMERN/A15 GAL | AP24: =BC24 -> 1787.4 | AQ24: =BF24 -> 15 GAL | AS24: =BE24 -> N/A | AT24: POLY-CRETE WR COVE BASE, SLOPE/PATCHING | AU24: KIT | AV24: =AT24&AU24 -> POLY-CRETE WR COVE BASE, SLOPE/PATCHINGKIT | AW24: 57.67 | AY24: =_xlfn.CONCAT(AZ24:BB24) -> MVP EPOXYN//A15 | AZ24: =MID(BD24,10,10) -> MVP EPOXY | BA24: =LEFT(BE24,2)&RIGHT(BE24,2) -> N//A | BB24: =LEFT(BF24,3) -> 15 | BC24: =IFERROR(VLOOKUP(BD24&BF24,AV:AW,2,FALSE),0) -> 1787.4 | BD24: RESUPRIME MVP EPOXY PRIMER | BE24: N/A | BF24: 15 GAL | BG24: PRIMER | BI24: {=IF(B3="","",IF(B3=$BL$3,$BE$8:$BE$10,IF(B3=$BL$4,$BE$14:$BE$17,$BE$6)))} -> N/A | BL24: CRYLAFLOR BOND ENHANCER TO P-101 | BM24: MMA | BN24: RESUFLOR PT 250 THICKENED EPOXY 2:1
I25: S-QSA-1 | J25: =_xlfn.CONCAT(K25:M25) -> QUARTZASH50LB | K25: QUARTZ | L25: ASH | M25: 50LB | X25: R-CYL-1 | Y25: RIO Yellow Colorant | Z25: =Table1[[#This Row],[D:D]] -> 28.05 | AA25: Pint | AD25: RIO | AE25: 25.5 | AF25: =Table1[[#This Row],[C:C]]*1.1 -> 28.05 | AI25: =IFERROR(VLOOKUP(X25,#REF!,8,FALSE),0) -> 0 | AN25: =PROD_ID_TABLE[[#This Row],[PROD ID]] -> 5531 OIL N//A1 Q | AO25: =_xlfn.CONCAT(BD25:BF25) -> RESUPRIME 5531 OIL STOP PRIMERN/A1 QT | AP25: =BC25 -> 48.26 | AQ25: =BF25 -> 1 QT | AS25: =BE25 -> N/A | AT25: POLY-CRETE HF ACCELERATOR LOW TEMPERATURE AID | AU25: 1 Qt | AV25: =AT25&AU25 -> POLY-CRETE HF ACCELERATOR LOW TEMPERATURE AID1 Qt | AW25: 43.8 | AY25: =_xlfn.CONCAT(AZ25:BB25) -> 5531 OIL N//A1 Q | AZ25: =MID(BD25,10,10) -> 5531 OIL | BA25: =LEFT(BE25,2)&RIGHT(BE25,2) -> N//A | BB25: =LEFT(BF25,3) -> 1 Q | BC25: =IFERROR(VLOOKUP(BD25&BF25,AV:AW,2,FALSE),0) -> 48.26 | BD25: RESUPRIME 5531 OIL STOP PRIMER | BE25: N/A | BF25: 1 QT | BG25: PRIMER | BI25: {=IF(B22="","",IF(B22=P!$BD$2,P!$BE$2,P!$BE$4:$BE$5))} | BL25: CRYLAFLOR SL FILLER BLEND TO G-201 | BM25: MMA | BN25: GP 3555 EPOFLEX 1:1
I26: S-QST-1 | J26: =_xlfn.CONCAT(K26:M26) -> TROWEL QUARTZGRAY50LB | K26: TROWEL QUARTZ | L26: GRAY | M26: 50LB | X26: R-EPT-15 | Y26: RIO Coat EPT 15 Gal Kit | Z26: =Table1[[#This Row],[D:D]] -> 825 | AA26: 15 gal | AD26: RIO | AE26: 750 | AF26: =Table1[[#This Row],[C:C]]*1.1 -> 825 | AI26: =IFERROR(VLOOKUP(X26,#REF!,8,FALSE),0) -> 0 | AN26: =PROD_ID_TABLE[[#This Row],[PROD ID]] -> 5531 OIL N//A5 G | AO26: =_xlfn.CONCAT(BD26:BF26) -> RESUPRIME 5531 OIL STOP PRIMERN/A5 GAL | AP26: =BC26 -> 123 | AQ26: =BF26 -> 5 GAL | AS26: =BE26 -> N/A | AT26: CRYLAFLOR BOND ENHANCER TO P-101 | AU26: KIT | AV26: =AT26&AU26 -> CRYLAFLOR BOND ENHANCER TO P-101KIT | AW26: 30 | AY26: =_xlfn.CONCAT(AZ26:BB26) -> 5531 OIL N//A5 G | AZ26: =MID(BD26,10,10) -> 5531 OIL | BA26: =LEFT(BE26,2)&RIGHT(BE26,2) -> N//A | BB26: =LEFT(BF26,3) -> 5 G | BC26: =IFERROR(VLOOKUP(BD26&BF26,AV:AW,2,FALSE),0) -> 123 | BD26: RESUPRIME 5531 OIL STOP PRIMER | BE26: N/A | BF26: 5 GAL | BG26: PRIMER | BH26: CRETE | BL26: CRYLAFLOR BOND MT METAL/TILE ENHANCER | BM26: MMA | BN26: RESUFLOR 3760 RCE RAPID CURE EPOXY
I27: S-AST-1 | J27: =_xlfn.CONCAT(K27:M27) -> TROWEL QUARTZASH50LB | K27: TROWEL QUARTZ | L27: ASH | M27: 50LB | X27: R-EPT-3 | Y27: RIO Coat EPT 3 Gal Kit | Z27: =Table1[[#This Row],[D:D]] -> 198 | AA27: 3 gal kit | AD27: RIO | AE27: 180 | AF27: =Table1[[#This Row],[C:C]]*1.1 -> 198 | AI27: =IFERROR(VLOOKUP(X27,#REF!,8,FALSE),0) -> 0 | AN27: E TF PLUS BLUE1.7 | AO27: =_xlfn.CONCAT(BD27:BF27) -> POLY-CRETE TF PLUS PRIMER/TOPCOATBLUEKIT | AP27: =BC27 -> 53.55 | AQ27: =BF27 -> KIT | AS27: =BE27 -> BLUE | AT27: CRYLAFLOR P-101 PRIMER | AU27: 5 GAL KIT | AV27: =AT27&AU27 -> CRYLAFLOR P-101 PRIMER5 GAL KIT | AW27: 323 | AY27: =_xlfn.CONCAT(AZ27:BB27) -> E TF PLUS BLUEKIT | AZ27: =MID(BD27,10,10) -> E TF PLUS | BA27: =LEFT(BE27,2)&RIGHT(BE27,2) -> BLUE | BB27: =LEFT(BF27,3) -> KIT | BC27: =IFERROR(VLOOKUP(BD27&BF27,AV:AW,2,FALSE),0) -> 53.55 | BD27: POLY-CRETE TF PLUS PRIMER/TOPCOAT | BE27: BLUE | BF27: KIT | BG27: CRETE | BH27: BLUE | BL27: CRYLAFLOR LTC ADDITIVE LOW TEMPERATURE | BM27: MMA
C28: {=_xlfn.SWITCH(SGC!M23,P!$C$17,P!$C$12,P!$C$14,P!$L$22,P!$C$15,P!$L$23:$L$25,P!$C$16,P!$L$26:$L$27)} -> ASH | D28: {=_xlfn.SWITCH(SGC!M38,P!$D$14,P!$M$44:$M$45,P!$D$15,P!$M$46:$M$47,P!$D$16,P!$M$33,P!$D$17,P!$M$34,P!$D$18,P!$M$35,P!$D$19,P!$M$36)} -> 5 GAL | E28: {=_xlfn.SWITCH(SGC!M58,P!$E$14,P!$L$37,P!$E$15,P!$L$38:$L$40,P!$E$16,P!$L$41:$L$43)} -> #N/A | F28: {=_xlfn.SWITCH(K3,P!$F$14,P!$M$44:$M$45,P!$F$15,P!$M$46:$M$47,P!$F$16,P!$M$48,P!$F$17,P!$M$49,P!$F$18,P!$M$50,P!$F$19,P!$M$51,P!$F$20,P!$M$52)} -> #N/A | G28: {=_xlfn.SWITCH(B21,P!$G$14,P!$L$53:$L$54,P!$G$15,P!$L$55:$L$63,P!$G$16,P!$L$64:$L$68)} -> #N/A | I28: R-A60-1 | J28: =_xlfn.CONCAT(K28:M28) -> ALUMINUM OXIDE60#50LB | K28: ALUMINUM OXIDE | L28: 60# | M28: 50LB | X28: R-ETM-C50 | Y28: RIO Trowel Clad Sand | Z28: =Table1[[#This Row],[D:D]] -> 19.8 | AA28: 50lb bag | AD28: RIO | AE28: 18 | AF28: =Table1[[#This Row],[C:C]]*1.1 -> 19.8 | AI28: =IFERROR(VLOOKUP(X28,#REF!,8,FALSE),0) -> 0 | AN28: E TF PLUS CHAL1.7 | AO28: =_xlfn.CONCAT(BD28:BF28) -> POLY-CRETE TF PLUS PRIMER/TOPCOATCHARCOALKIT | AP28: =BC28 -> 53.55 | AQ28: =BF28 -> KIT | AS28: =BE28 -> CHARCOAL | AT28: CRYLAFLOR G-201 BINDER | AU28: 5 GAL KIT | AV28: =AT28&AU28 -> CRYLAFLOR G-201 BINDER5 GAL KIT | AW28: 341.92 | AY28: =_xlfn.CONCAT(AZ28:BB28) -> E TF PLUS CHALKIT | AZ28: =MID(BD28,10,10) -> E TF PLUS | BA28: =LEFT(BE28,2)&RIGHT(BE28,2) -> CHAL | BB28: =LEFT(BF28,3) -> KIT | BC28: =IFERROR(VLOOKUP(BD28&BF28,AV:AW,2,FALSE),0) -> 53.55 | BD28: POLY-CRETE TF PLUS PRIMER/TOPCOAT | BE28: CHARCOAL | BF28: KIT | BG28: CRETE | BH28: CHARCOAL | BL28: CRYLAFLOR CLEAN SOLVENT TO CLEAN TOOLS | BM28: MMA
A29: {=_xlfn.SWITCH(SGC!C6,P!$A$14,P!$M$14,P!$A$15,P!$M$15,P!$A$16,P!$M$16,P!$A$17,P!$M$17:$M$18,P!$A$18,P!$M$19)} -> 5 GAL | B29: {=_xlfn.IFS(SGC!C38=P!$B$14,P!$M$20:$M$21)} -> 2.5 GAL | C29: =IF(SGC!M23=P!$C$14,P!$M$22,P!$M$23) -> 40LB | D29: 50 GAL | F29: CLEAR | G29: =IF(SGC!C23=P!$G$16,P!$M$64,P!$M$53) -> PINT | I29: R-MMB-5 | J29: =_xlfn.CONCAT(K29:M29) -> SGC SHIELD BODY COATN/A5 GAL | K29: SGC SHIELD BODY COAT | L29: N/A | M29: 5 GAL | X29: R-MBP-10 | Y29: SGC MMA BPO Catalyst 10 lbs | Z29: =Table1[[#This Row],[D:D]] -> 264 | AA29: 10lb box | AD29: RIO | AE29: 240 | AF29: =Table1[[#This Row],[C:C]]*1.1 -> 264 | AI29: =IFERROR(VLOOKUP(X29,#REF!,8,FALSE),0) -> 0 | AN29: E TF PLUS CHUT1.7 | AO29: =_xlfn.CONCAT(BD29:BF29) -> POLY-CRETE TF PLUS PRIMER/TOPCOATCHESTNUTKIT | AP29: =BC29 -> 53.55 | AQ29: =BF29 -> KIT | AS29: =BE29 -> CHESTNUT | AT29: CRYLAFLOR T-301 TOPCOAT | AU29: 5 GAL KIT | AV29: =AT29&AU29 -> CRYLAFLOR T-301 TOPCOAT5 GAL KIT | AW29: 329.56 | AY29: =_xlfn.CONCAT(AZ29:BB29) -> E TF PLUS CHUTKIT | AZ29: =MID(BD29,10,10) -> E TF PLUS | BA29: =LEFT(BE29,2)&RIGHT(BE29,2) -> CHUT | BB29: =LEFT(BF29,3) -> KIT | BC29: =IFERROR(VLOOKUP(BD29&BF29,AV:AW,2,FALSE),0) -> 53.55 | BD29: POLY-CRETE TF PLUS PRIMER/TOPCOAT | BE29: CHESTNUT | BF29: KIT | BG29: CRETE | BH29: CHESTNUT
B30: 25 GAL | F30: PIGMENTED | I30: R-MMB-50 | J30: =_xlfn.CONCAT(K30:M30) -> SGC SHIELD BODY COATN/A50 GAL | K30: SGC SHIELD BODY COAT | L30: N/A | M30: 50 GAL | X30: R-MMA-5 | Y30: RIO MMA Bonding Additive | Z30: =Table1[[#This Row],[D:D]] -> 341 | AA30: 5 gal | AD30: RIO | AE30: 310 | AF30: =Table1[[#This Row],[C:C]]*1.1 -> 341 | AI30: =IFERROR(VLOOKUP(X30,#REF!,8,FALSE),0) -> 0 | AN30: E TF PLUS COAY1.7 | AO30: =_xlfn.CONCAT(BD30:BF30) -> POLY-CRETE TF PLUS PRIMER/TOPCOATCONCRETE GRAYKIT | AP30: =BC30 -> 53.55 | AQ30: =BF30 -> KIT | AS30: =BE30 -> CONCRETE GRAY | AT30: CRYLAFLOR T-303 FLEXIBLE TOPCOAT | AU30: 5 GAL KIT | AV30: =AT30&AU30 -> CRYLAFLOR T-303 FLEXIBLE TOPCOAT5 GAL KIT | AW30: 424.9 | AY30: =_xlfn.CONCAT(AZ30:BB30) -> E TF PLUS COAYKIT | AZ30: =MID(BD30,10,10) -> E TF PLUS | BA30: =LEFT(BE30,2)&RIGHT(BE30,2) -> COAY | BB30: =LEFT(BF30,3) -> KIT | BC30: =IFERROR(VLOOKUP(BD30&BF30,AV:AW,2,FALSE),0) -> 53.55 | BD30: POLY-CRETE TF PLUS PRIMER/TOPCOAT | BE30: CONCRETE GRAY | BF30: KIT | BG30: CRETE | BH30: CONCRETE GRAY
B31: 3 GAL | E31: =IF(SGC!M58=P!$E$15,P!$M$38,P!$M$41) -> TUBE | I31: R-MMT-5 | J31: =_xlfn.CONCAT(K31:M31) -> SGC SHIELD TOP COATN/A5 GAL | K31: SGC SHIELD TOP COAT | L31: N/A | M31: 5 GAL | X31: R-MMB-5 | Y31: SGC Shield Body Coat 5 Gal | Z31: =Table1[[#This Row],[D:D]] -> 302.5 | AA31: 5 gal | AD31: RIO | AE31: 275 | AF31: =Table1[[#This Row],[C:C]]*1.1 -> 302.5 | AI31: =IFERROR(VLOOKUP(X31,#REF!,8,FALSE),0) -> 0 | AN31: E TF PLUS DAAY1.7 | AO31: =_xlfn.CONCAT(BD31:BF31) -> POLY-CRETE TF PLUS PRIMER/TOPCOATDARK GRAYKIT | AP31: =BC31 -> 53.55 | AQ31: =BF31 -> KIT | AS31: =BE31 -> DARK GRAY | AT31: CRYLAFLOR COVE | AU31: 1 GAL KIT | AV31: =AT31&AU31 -> CRYLAFLOR COVE1 GAL KIT | AW31: 117.7 | AY31: =_xlfn.CONCAT(AZ31:BB31) -> E TF PLUS DAAYKIT | AZ31: =MID(BD31,10,10) -> E TF PLUS | BA31: =LEFT(BE31,2)&RIGHT(BE31,2) -> DAAY | BB31: =LEFT(BF31,3) -> KIT | BC31: =IFERROR(VLOOKUP(BD31&BF31,AV:AW,2,FALSE),0) -> 53.55 | BD31: POLY-CRETE TF PLUS PRIMER/TOPCOAT | BE31: DARK GRAY | BF31: KIT | BG31: CRETE | BH31: DARK GRAY
E32: CASE | I32: R-MMT-50 | J32: =_xlfn.CONCAT(K32:M32) -> SGC SHIELD TOP COATN/A50 GAL | K32: SGC SHIELD TOP COAT | L32: N/A | M32: 50 GAL | X32: R-MMB-50 | Y32: SGC Shield Body Coat 50 Gal | Z32: =Table1[[#This Row],[D:D]] -> 2915 | AA32: 50 gal | AD32: RIO | AE32: 2650 | AF32: =Table1[[#This Row],[C:C]]*1.1 -> 2915 | AI32: =IFERROR(VLOOKUP(X32,#REF!,8,FALSE),0) -> 0 | AN32: E TF PLUS GREN1.7 | AO32: =_xlfn.CONCAT(BD32:BF32) -> POLY-CRETE TF PLUS PRIMER/TOPCOATGREENKIT | AP32: =BC32 -> 53.55 | AQ32: =BF32 -> KIT | AS32: =BE32 -> GREEN | AT32: CRYLAFLOR CURE (BPO) | AU32: 5 LB KIT | AV32: =AT32&AU32 -> CRYLAFLOR CURE (BPO)5 LB KIT | AW32: 122.41 | AY32: =_xlfn.CONCAT(AZ32:BB32) -> E TF PLUS GRENKIT | AZ32: =MID(BD32,10,10) -> E TF PLUS | BA32: =LEFT(BE32,2)&RIGHT(BE32,2) -> GREN | BB32: =LEFT(BF32,3) -> KIT | BC32: =IFERROR(VLOOKUP(BD32&BF32,AV:AW,2,FALSE),0) -> 53.55 | BD32: POLY-CRETE TF PLUS PRIMER/TOPCOAT | BE32: GREEN | BF32: KIT | BG32: CRETE | BH32: GREEN
I33: R-MBP-10 | J33: =_xlfn.CONCAT(K33:M33) -> SGC BPO CATALYSTN/A10LB BOX | K33: SGC BPO CATALYST | L33: N/A | M33: 10LB BOX | X33: R-MMC-5 | Y33: SGC Coat MMA Cleaner 5 Gal | Z33: =Table1[[#This Row],[D:D]] -> 264 | AA33: 5 gal | AD33: RIO | AE33: 240 | AF33: =Table1[[#This Row],[C:C]]*1.1 -> 264 | AI33: =IFERROR(VLOOKUP(X33,#REF!,8,FALSE),0) -> 0 | AN33: E TF PLUS GRAY1.7 | AO33: =_xlfn.CONCAT(BD33:BF33) -> POLY-CRETE TF PLUS PRIMER/TOPCOATGRAYKIT | AP33: =BC33 -> 53.55 | AQ33: =BF33 -> KIT | AS33: =BE33 -> GRAY | AT33: CRYLAFLOR COLOR - BACKGROUND ONLY | AU33: KIT | AV33: =AT33&AU33 -> CRYLAFLOR COLOR - BACKGROUND ONLYKIT | AW33: 112.8 | AY33: =_xlfn.CONCAT(AZ33:BB33) -> E TF PLUS GRAYKIT | AZ33: =MID(BD33,10,10) -> E TF PLUS | BA33: =LEFT(BE33,2)&RIGHT(BE33,2) -> GRAY | BB33: =LEFT(BF33,3) -> KIT | BC33: =IFERROR(VLOOKUP(BD33&BF33,AV:AW,2,FALSE),0) -> 53.55 | BD33: POLY-CRETE TF PLUS PRIMER/TOPCOAT | BE33: GRAY | BF33: KIT | BG33: CRETE | BH33: GRAY
D34: =UPPER(B15) | I34: R-MMC-5 | J34: =_xlfn.CONCAT(K34:M34) -> SGC COAT MMA CLEANERN/A5 GAL | K34: SGC COAT MMA CLEANER | L34: N/A | M34: 5 GAL | X34: R-MMP-5 | Y34: SGC MMA Primer | Z34: =Table1[[#This Row],[D:D]] -> 330 | AA34: 5 gal | AD34: RIO | AE34: 300 | AF34: =Table1[[#This Row],[C:C]]*1.1 -> 330 | AI34: =IFERROR(VLOOKUP(X34,#REF!,8,FALSE),0) -> 0 | AN34: E TF PLUS REED1.7 | AO34: =_xlfn.CONCAT(BD34:BF34) -> POLY-CRETE TF PLUS PRIMER/TOPCOATREDKIT | AP34: =BC34 -> 53.55 | AQ34: =BF34 -> KIT | AS34: =BE34 -> RED | AT34: CRYLAFLOR BOND MT METAL/TILE ENHANCER | AU34: KIT | AV34: =AT34&AU34 -> CRYLAFLOR BOND MT METAL/TILE ENHANCERKIT | AW34: 85.8 | AY34: =_xlfn.CONCAT(AZ34:BB34) -> E TF PLUS REEDKIT | AZ34: =MID(BD34,10,10) -> E TF PLUS | BA34: =LEFT(BE34,2)&RIGHT(BE34,2) -> REED | BB34: =LEFT(BF34,3) -> KIT | BC34: =IFERROR(VLOOKUP(BD34&BF34,AV:AW,2,FALSE),0) -> 53.55 | BD34: POLY-CRETE TF PLUS PRIMER/TOPCOAT | BE34: RED | BF34: KIT | BG34: CRETE | BH34: RED
I35: R-MMP-5 | J35: =_xlfn.CONCAT(K35:M35) -> SGC MMA PRIMERN/A5 GAL | K35: SGC MMA PRIMER | L35: N/A | M35: 5 GAL | X35: R-MMT-5 | Y35: SGC Shield Topcoat 5 Gal | Z35: =Table1[[#This Row],[D:D]] -> 330 | AA35: 5 gal | AD35: RIO | AE35: 300 | AF35: =Table1[[#This Row],[C:C]]*1.1 -> 330 | AI35: =IFERROR(VLOOKUP(X35,#REF!,8,FALSE),0) -> 0 | AN35: E TF PLUS BLUE0.4 | AO35: =_xlfn.CONCAT(BD35:BF35) -> POLY-CRETE TF PLUS PRIMER/TOPCOATBLUEKIT | AP35: =BC35 -> 53.55 | AQ35: =BF35 -> KIT | AS35: =BE35 -> BLUE | AT35: CRYLAFLOR CLEAN SOLVENT TO CLEAN TOOLS | AU35: KIT | AV35: =AT35&AU35 -> CRYLAFLOR CLEAN SOLVENT TO CLEAN TOOLSKIT | AW35: 37.8 | AY35: =_xlfn.CONCAT(AZ35:BB35) -> E TF PLUS BLUEKIT | AZ35: =MID(BD35,10,10) -> E TF PLUS | BA35: =LEFT(BE35,2)&RIGHT(BE35,2) -> BLUE | BB35: =LEFT(BF35,3) -> KIT | BC35: =IFERROR(VLOOKUP(BD35&BF35,AV:AW,2,FALSE),0) -> 53.55 | BD35: POLY-CRETE TF PLUS PRIMER/TOPCOAT | BE35: BLUE | BF35: KIT | BG35: CRETE | BH35: N/A
I36: R-MMA-5 | J36: =_xlfn.CONCAT(K36:M36) -> RIO MMA BONDING ADDITIVEN/A5 GAL | K36: RIO MMA BONDING ADDITIVE | L36: N/A | M36: 5 GAL | X36: R-MMT-50 | Y36: SGC Shield Topcoat 50 Gal | Z36: =Table1[[#This Row],[D:D]] -> 2915 | AA36: 50 gal | AD36: RIO | AE36: 2650 | AF36: =Table1[[#This Row],[C:C]]*1.1 -> 2915 | AI36: =IFERROR(VLOOKUP(X36,#REF!,8,FALSE),0) -> 0 | AN36: E TF PLUS CHAL0.4 | AO36: =_xlfn.CONCAT(BD36:BF36) -> POLY-CRETE TF PLUS PRIMER/TOPCOATCHARCOALKIT | AP36: =BC36 -> 53.55 | AQ36: =BF36 -> KIT | AS36: =BE36 -> CHARCOAL | AT36: CRYLAFLOR LTC ADDITIVE LOW TEMPERATURE | AU36: KIT | AV36: =AT36&AU36 -> CRYLAFLOR LTC ADDITIVE LOW TEMPERATUREKIT | AW36: 46.8 | AY36: =_xlfn.CONCAT(AZ36:BB36) -> E TF PLUS CHALKIT | AZ36: =MID(BD36,10,10) -> E TF PLUS | BA36: =LEFT(BE36,2)&RIGHT(BE36,2) -> CHAL | BB36: =LEFT(BF36,3) -> KIT | BC36: =IFERROR(VLOOKUP(BD36&BF36,AV:AW,2,FALSE),0) -> 53.55 | BD36: POLY-CRETE TF PLUS PRIMER/TOPCOAT | BE36: CHARCOAL | BF36: KIT | BG36: CRETE | BH36: 3 GAL | BI36: {=IF(C35="","",_xlfn.SWITCH(C35,P!$BJ$36,P!$BH$46:$BH$47,P!$BJ$37,P!$BH$38,P!$BJ$38,P!$BH$45,P!$BJ$39,P!$BH$43,P!$BJ$40,P!$BH$42,P!$BJ$41,P!$BH$44,P!$BJ$42,P!$BH$40:$BH$41,P!$BJ$43,P!$BH$48))} | BJ36: POLY-CRETE COLOR-FAST | BK36: CRETE | BL36: 5115 MORTAR AGGREGATE BLEND | BM36: AGG
I37: NP-1 | J37: =_xlfn.CONCAT(K37:M37) -> NP-1 TUBES (30 TUBE/CASE)N/ATUBE | K37: NP-1 TUBES (30 TUBE/CASE) | L37: N/A | M37: TUBE | X37: ROAD10600 | Y37: Roadware 10 Minute Concrete Mender 600ML | Z37: =Table1[[#This Row],[D:D]] -> 65.219 | AA37: Tube | AD37: RIO | AE37: 59.29 | AF37: =Table1[[#This Row],[C:C]]*1.1 -> 65.219 | AI37: =IFERROR(VLOOKUP(X37,#REF!,8,FALSE),0) -> 0 | AN37: E TF PLUS CHUT0.4 | AO37: =_xlfn.CONCAT(BD37:BF37) -> POLY-CRETE TF PLUS PRIMER/TOPCOATCHESTNUTKIT | AP37: =BC37 -> 53.55 | AQ37: =BF37 -> KIT | AS37: =BE37 -> CHESTNUT | AT37: CRYLAFLOR SL FILLER BLEND TO G-201 | AU37: KIT | AV37: =AT37&AU37 -> CRYLAFLOR SL FILLER BLEND TO G-201KIT | AW37: 23.4 | AY37: =_xlfn.CONCAT(AZ37:BB37) -> E TF PLUS CHUTKIT | AZ37: =MID(BD37,10,10) -> E TF PLUS | BA37: =LEFT(BE37,2)&RIGHT(BE37,2) -> CHUT | BB37: =LEFT(BF37,3) -> KIT | BC37: =IFERROR(VLOOKUP(BD37&BF37,AV:AW,2,FALSE),0) -> 53.55 | BD37: POLY-CRETE TF PLUS PRIMER/TOPCOAT | BE37: CHESTNUT | BF37: KIT | BG37: CRETE | BH37: 15 GAL | BJ37: POLY-CRETE HF ACCELERATOR LOW TEMPERATURE AID | BK37: CRETE | BL37: 7310 PEA GRAVEL 3/16 X 3/8 | BM37: AGG
I38: JS4U-SG | J38: =_xlfn.CONCAT(K38:M38) -> 600 UV (SSP JS-600 ALIPHATIC POLYUREA)STANDARD GRAY1 GAL BOX | K38: 600 UV (SSP JS-600 ALIPHATIC POLYUREA) | L38: STANDARD GRAY | M38: 1 GAL BOX | X38: R-S20-1 | Y38: 20/40 Silica Sand | Z38: =Table1[[#This Row],[D:D]] -> 24.2 | AA38: Bag | AD38: RIO | AE38: 22 | AF38: =Table1[[#This Row],[C:C]]*1.1 -> 24.2 | AI38: =IFERROR(VLOOKUP(X38,#REF!,8,FALSE),0) -> 0 | AN38: E TF PLUS COAY0.4 | AO38: =_xlfn.CONCAT(BD38:BF38) -> POLY-CRETE TF PLUS PRIMER/TOPCOATCONCRETE GRAYKIT | AP38: =BC38 -> 53.55 | AQ38: =BF38 -> KIT | AS38: =BE38 -> CONCRETE GRAY | AT38: RESUDECK FLA CLEAR ALIPHATIC POLYASPARTIC TOPCOAT | AU38: 2 GAL | AV38: =AT38&AU38 -> RESUDECK FLA CLEAR ALIPHATIC POLYASPARTIC TOPCOAT2 GAL | AW38: 215.98 | AY38: =_xlfn.CONCAT(AZ38:BB38) -> E TF PLUS COAYKIT | AZ38: =MID(BD38,10,10) -> E TF PLUS | BA38: =LEFT(BE38,2)&RIGHT(BE38,2) -> COAY | BB38: =LEFT(BF38,3) -> KIT | BC38: =IFERROR(VLOOKUP(BD38&BF38,AV:AW,2,FALSE),0) -> 53.55 | BD38: POLY-CRETE TF PLUS PRIMER/TOPCOAT | BE38: CONCRETE GRAY | BF38: KIT | BG38: CRETE | BH38: 1 QT | BJ38: POLY-CRETE HF HS URETHANE CONCRETE COATING | BK38: CRETE | BL38: F-60 | BM38: AGG
H39: 600 UVGRAY AREA1 GAL BOX | I39: JS4U-GA | J39: =_xlfn.CONCAT(K39:M39) -> 600 UV (SSP JS-600 ALIPHATIC POLYUREA)GRAY AREA1 GAL BOX | K39: 600 UV (SSP JS-600 ALIPHATIC POLYUREA) | L39: GRAY AREA | M39: 1 GAL BOX | X39: S-UPA-3 | Y39: SGC Coat UPA | Z39: =Table1[[#This Row],[D:D]] -> 396 | AA39: 3 gal kit | AD39: RIO | AE39: =120*3 -> 360 | AF39: =Table1[[#This Row],[C:C]]*1.1 -> 396 | AI39: =IFERROR(VLOOKUP(X39,#REF!,8,FALSE),0) -> 0 | AN39: E TF PLUS DAAY0.4 | AO39: =_xlfn.CONCAT(BD39:BF39) -> POLY-CRETE TF PLUS PRIMER/TOPCOATDARK GRAYKIT | AP39: =BC39 -> 53.55 | AQ39: =BF39 -> KIT | AS39: =BE39 -> DARK GRAY | AT39: ACCELERA 4850 GROUT/TOPCOAT POLYASPARTIC | AU39: 3 GAL | AV39: =AT39&AU39 -> ACCELERA 4850 GROUT/TOPCOAT POLYASPARTIC3 GAL | AW39: 466.86 | AY39: =_xlfn.CONCAT(AZ39:BB39) -> E TF PLUS DAAYKIT | AZ39: =MID(BD39,10,10) -> E TF PLUS | BA39: =LEFT(BE39,2)&RIGHT(BE39,2) -> DAAY | BB39: =LEFT(BF39,3) -> KIT | BC39: =IFERROR(VLOOKUP(BD39&BF39,AV:AW,2,FALSE),0) -> 53.55 | BD39: POLY-CRETE TF PLUS PRIMER/TOPCOAT | BE39: DARK GRAY | BF39: KIT | BG39: CRETE | BH39: 5 GAL | BJ39: POLY-CRETE MD HS URETHANE CONCRETE COATING | BK39: CRETE | BL39: 1-16IN DECO FLAKE - 40LB BAG | BM39: AGG
I40: JS4U-CG | J40: =_xlfn.CONCAT(K40:M40) -> 600 UV (SSP JS-600 ALIPHATIC POLYUREA)CHATEAU GRAY1 GAL BOX | K40: 600 UV (SSP JS-600 ALIPHATIC POLYUREA) | L40: CHATEAU GRAY | M40: 1 GAL BOX | X40: R-UHW-1.5 | Y40: RIO Urethane High Wear Kit | Z40: =Table1[[#This Row],[D:D]] -> 374 | AA40: 1.5 Gal | AD40: RIO | AE40: 340 | AF40: =Table1[[#This Row],[C:C]]*1.1 -> 374 | AI40: =IFERROR(VLOOKUP(X40,#REF!,8,FALSE),0) -> 0 | AN40: E TF PLUS GREN0.4 | AO40: =_xlfn.CONCAT(BD40:BF40) -> POLY-CRETE TF PLUS PRIMER/TOPCOATGREENKIT | AP40: =BC40 -> 53.55 | AQ40: =BF40 -> KIT | AS40: =BE40 -> GREEN | AT40: ACCELERA 4850 GROUT/TOPCOAT POLYASPARTIC | AU40: 15 GAL | AV40: =AT40&AU40 -> ACCELERA 4850 GROUT/TOPCOAT POLYASPARTIC15 GAL | AW40: 2126.25 | AY40: =_xlfn.CONCAT(AZ40:BB40) -> E TF PLUS GRENKIT | AZ40: =MID(BD40,10,10) -> E TF PLUS | BA40: =LEFT(BE40,2)&RIGHT(BE40,2) -> GREN | BB40: =LEFT(BF40,3) -> KIT | BC40: =IFERROR(VLOOKUP(BD40&BF40,AV:AW,2,FALSE),0) -> 53.55 | BD40: POLY-CRETE TF PLUS PRIMER/TOPCOAT | BE40: GREEN | BF40: KIT | BG40: CRETE | BH40: 0.44 Gal | BJ40: POLY-CRETE SL HS SELF LEVELING URETHANE | BK40: CRETE | BL40: 1-8IN DECO FLAKE - 40LB BAG | BM40: AGG
...

Sheet INFO
B2: Project Name: | F2: Country: | H2: Job #:
B4: Project Manager: | F4: Super/Foreman:
B6: Scope/Schedule
B7: PHASE / SCOPE / COP | C7: Installed System | D7: SQ FT | E7: LF Cove | F7: LF Joints | G7: Material Delivery Date | H7: Start Time | I7: Install Start Date | J7: Install End Date
B16: Jobsite Information
B18: Ship To Address: | F18: Install Address:
C22: CITY | D22: STATE | E22: ZIP | H22: CITY | I22: STATE | J22: ZIP
B24: Site Contact: | G24: Union: | I24: x
B25: Phone? | G25: Non-Union:
G26: Prevailing Wage:
B28: Pre-Job Checklist
B30: Contract Executed: | E30: Heat: | H30: Complete:
B31: Installation Scheduled: | E31: Lights: | H31: Final Walk:
B32: Materials Ordered: | E32: Power: | H32: Return Mat:
B33: Rental Booked: | E33: Trash: | H33: New Building:
B35: General Project and Flooring System Info
B47: Financials
B49: Tab | C49: Subtotal | E49: Total | G49: Markup % | H49: Gross Profit % | I49: Bid Amount
B50: SW | C50: =SW!N91 -> 0 | E50: =SW!N96 -> 0 | G50: =SW!R92 -> 0 | H50: =SW!R93 -> 0 | I50: =SW!Q97 -> 0
B51: SIKA | C51: =SIKA!N68 -> 0 | E51: =SIKA!N73 -> 0 | G51: =SIKA!R69 -> 0 | H51: =SIKA!R70 -> 0 | I51: =SIKA!Q74 -> 0
B52: RIO | C52: =SGC!N77 -> 0 | E52: =SGC!N82 -> 0 | G52: =SGC!R78 -> 0 | H52: =SGC!R79 -> 0 | I52: =SGC!Q83 -> 0
B53: BLANK | C53: =BLANK!N46 -> 0 | E53: =BLANK!N51 -> 0 | G53: =BLANK!R47 -> 0 | H53: =BLANK!R48 -> 0 | I53: =BLANK!Q52 -> 0
B54: Grand Total | I54: =SUM(I50:I53) -> 0
G56: Total Sq. Ft. | H56: =SUM($D$8:$D$14) -> 0 | I56: Cost Per Sq. Ft. | J56: =IFERROR($I$54/$H$56, "")

Sheet FIELD
B2: **TO EXPORT TABS -"File" / "Export" / "Create PDF/XPS Document" / enter file name / choose save location / "Publish"
B4: =IF(INFO!B2=0,"",INFO!B2) -> Project Name: | C4: =IF(INFO!C2=0,"",INFO!C2) | G4: =IF(INFO!H2=0,"",INFO!H2) -> Job #: | I4: =IF(INFO!I2=0,"",INFO!I2)
B6: =IF(INFO!B4=0,"",INFO!B4) -> Project Manager: | C6: =IF(INFO!C4=0,"",INFO!C4) | G6: =IF(INFO!F4=0,"",INFO!F4) -> Super/Foreman: | I6: =IF(INFO!H4=0,"",INFO!H4)
B8: Scope/Schedule
B9: =IF(INFO!B7=0,"",INFO!B7) -> PHASE / SCOPE / COP | C9: =IF(INFO!C7=0,"",INFO!C7) -> Installed System | D9: =IF(INFO!D7=0,"",INFO!D7) -> SQ FT | E9: =IF(INFO!E7=0,"",INFO!E7) -> LF Cove | F9: =IF(INFO!F7=0,"",INFO!F7) -> LF Joints | G9: =IF(INFO!G7=0,"",INFO!G7) -> Material Delivery Date | H9: =IF(INFO!H7=0,"",INFO!H7) -> Start Time | I9: =IF(INFO!I7=0,"",INFO!I7) -> Install Start Date | J9: =IF(INFO!J7=0,"",INFO!J7) -> Install End Date
B10: =IF(INFO!B8=0,"",INFO!B8) | C10: =IF(INFO!C8=0,"",INFO!C8) | D10: =IF(INFO!D8=0,"",INFO!D8) | E10: =IF(INFO!E8=0,"",INFO!E8) | F10: =IF(INFO!F8=0,"",INFO!F8) | G10: =IF(INFO!G8=0,"",INFO!G8) | H10: =IF(INFO!H8=0,"",INFO!H8) | I10: =IF(INFO!I8=0,"",INFO!I8) | J10: =IF(INFO!J8=0,"",INFO!J8)
B11: =IF(INFO!B9=0,"",INFO!B9) | C11: =IF(INFO!C9=0,"",INFO!C9) | D11: =IF(INFO!D9=0,"",INFO!D9) | E11: =IF(INFO!E9=0,"",INFO!E9) | F11: =IF(INFO!F9=0,"",INFO!F9) | G11: =IF(INFO!G9=0,"",INFO!G9) | H11: =IF(INFO!H9=0,"",INFO!H9) | I11: =IF(INFO!I9=0,"",INFO!I9) | J11: =IF(INFO!J9=0,"",INFO!J9)
B12: =IF(INFO!B10=0,"",INFO!B10) | C12: =IF(INFO!C10=0,"",INFO!C10) | D12: =IF(INFO!D10=0,"",INFO!D10) | E12: =IF(INFO!E10=0,"",INFO!E10) | F12: =IF(INFO!F10=0,"",INFO!F10) | G12: =IF(INFO!G10=0,"",INFO!G10) | H12: =IF(INFO!H10=0,"",INFO!H10) | I12: =IF(INFO!I10=0,"",INFO!I10) | J12: =IF(INFO!J10=0,"",INFO!J10)
B13: =IF(INFO!B11=0,"",INFO!B11) | C13: =IF(INFO!C11=0,"",INFO!C11) | D13: =IF(INFO!D11=0,"",INFO!D11) | E13: =IF(INFO!E11=0,"",INFO!E11) | F13: =IF(INFO!F11=0,"",INFO!F11) | G13: =IF(INFO!G11=0,"",INFO!G11) | H13: =IF(INFO!H11=0,"",INFO!H11) | I13: =IF(INFO!I11=0,"",INFO!I11) | J13: =IF(INFO!J11=0,"",INFO!J11)
B14: =IF(INFO!B12=0,"",INFO!B12) | C14: =IF(INFO!C12=0,"",INFO!C12) | D14: =IF(INFO!D12=0,"",INFO!D12) | E14: =IF(INFO!E12=0,"",INFO!E12) | F14: =IF(INFO!F12=0,"",INFO!F12) | G14: =IF(INFO!G12=0,"",INFO!G12) | H14: =IF(INFO!H12=0,"",INFO!H12) | I14: =IF(INFO!I12=0,"",INFO!I12) | J14: =IF(INFO!J12=0,"",INFO!J12)
B15: =IF(INFO!B13=0,"",INFO!B13) | C15: =IF(INFO!C13=0,"",INFO!C13) | D15: =IF(INFO!D13=0,"",INFO!D13) | E15: =IF(INFO!E13=0,"",INFO!E13) | F15: =IF(INFO!F13=0,"",INFO!F13) | G15: =IF(INFO!G13=0,"",INFO!G13) | H15: =IF(INFO!H13=0,"",INFO!H13) | I15: =IF(INFO!I13=0,"",INFO!I13) | J15: =IF(INFO!J13=0,"",INFO!J13)
B16: =IF(INFO!B14=0,"",INFO!B14) | C16: =IF(INFO!C14=0,"",INFO!C14) | D16: =IF(INFO!D14=0,"",INFO!D14) | E16: =IF(INFO!E14=0,"",INFO!E14) | F16: =IF(INFO!F14=0,"",INFO!F14) | G16: =IF(INFO!G14=0,"",INFO!G14) | H16: =IF(INFO!H14=0,"",INFO!H14) | I16: =IF(INFO!I14=0,"",INFO!I14) | J16: =IF(INFO!J14=0,"",INFO!J14)
B18: Jobsite Information
B20: =IF(INFO!B18=0,"",INFO!B18) -> Ship To Address: | C20: =IF(INFO!C18=0,"",INFO!C18) | F20: Install Address: | H20: =IF(INFO!H18=0,"",INFO!H18)
C21: =IF(INFO!C19=0,"",INFO!C19) | H21: =IF(INFO!H19=0,"",INFO!H19)
C22: =IF(INFO!C20=0,"",INFO!C20) | H22: =IF(INFO!H20=0,"",INFO!H20)
C23: =IF(INFO!C21=0,"",INFO!C21) | D23: =IF(INFO!D21=0,"",INFO!D21) | E23: =IF(INFO!E21=0,"",INFO!E21) | H23: =IF(INFO!H21=0,"",INFO!H21) | I23: =IF(INFO!I21=0,"",INFO!I21) | J23: =IF(INFO!J21=0,"",INFO!J21)
C24: CITY | D24: STATE | E24: ZIP | H24: CITY | I24: STATE | J24: ZIP
B26: =IF(INFO!B24=0,"",INFO!B24) -> Site Contact: | C26: =IF(INFO!C24=0,"",INFO!C24) | G26: =IF(INFO!G24=0,"",INFO!G24) -> Union: | I26: =IF(INFO!I24=0,"",INFO!I24) -> x
C27: =IF(INFO!C25=0,"",INFO!C25) | G27: =IF(INFO!G25=0,"",INFO!G25) -> Non-Union: | I27: =IF(INFO!I25=0,"",INFO!I25)
C28: =IF(INFO!C26=0,"",INFO!C26) | G28: =IF(INFO!G26=0,"",INFO!G26) -> Prevailing Wage: | I28: =IF(INFO!I26=0,"",INFO!I26)
B30: Pre-Job Checklist
B32: =IF(INFO!B30=0,"",INFO!B30) -> Contract Executed: | C32: =IF(INFO!C30=0,"",INFO!C30) | E32: =IF(INFO!E30=0,"",INFO!E30) -> Heat: | F32: =IF(INFO!F30=0,"",INFO!F30) | H32: =IF(INFO!H30=0,"",INFO!H30) -> Complete: | J32: =IF(INFO!J30=0,"",INFO!J30)
B33: =IF(INFO!B31=0,"",INFO!B31) -> Installation Scheduled: | C33: =IF(INFO!C31=0,"",INFO!C31) | E33: =IF(INFO!E31=0,"",INFO!E31) -> Lights: | F33: =IF(INFO!F31=0,"",INFO!F31) | H33: =IF(INFO!H31=0,"",INFO!H31) -> Final Walk: | J33: =IF(INFO!J31=0,"",INFO!J31)
B34: =IF(INFO!B32=0,"",INFO!B32) -> Materials Ordered: | C34: =IF(INFO!C32=0,"",INFO!C32) | E34: =IF(INFO!E32=0,"",INFO!E32) -> Power: | F34: =IF(INFO!F32=0,"",INFO!F32) | H34: =IF(INFO!H32=0,"",INFO!H32) -> Return Mat: | J34: =IF(INFO!J32=0,"",INFO!J32)
B35: =IF(INFO!B33=0,"",INFO!B33) -> Rental Booked: | C35: =IF(INFO!C33=0,"",INFO!C33) | E35: =IF(INFO!E33=0,"",INFO!E33) -> Trash: | F35: =IF(INFO!F33=0,"",INFO!F33) | H35: =IF(INFO!H33=0,"",INFO!H33) -> New Building: | J35: =IF(INFO!J33=0,"",INFO!J33)
B37: General Project and Flooring System Info
B39: =IF(INFO!B37="","",INFO!B37)
B49: Labor Budget
B51: Scope | C51: Tab | F51: Crew | G51: Days | H51: Rate/Day | I51: Total Man-Days
B52: {=_xlfn.LET( _xlpm.gAll, _xlfn.VSTACK(SW!G69:G77, SGC!G55:G63, SIKA!G45:G54, BLANK!G31:G40), _xlpm.fAll, _xlfn.VSTACK(SW!F69:F77, SGC!F55:F63, SIKA!F45:F54, BLANK!F31:F40), _xlpm.cAll, _xlfn.VSTACK(SW!C69:C77, SGC!C55:C63, SIKA!C45:C54, BLANK!C31:C40), _xlpm.mask, (_xlpm.gAll<>"")+(_xlpm.fAll<>""), _xlpm.n, SUM(--_xlpm.mask), IF(_xlpm.n=0, "", _xlfn.LET( _xlpm.cKeep, _xlfn._xlws.FILTER(_xlpm.cAll, _xlpm.mask), _xlpm.k, MIN(ROWS(B50:B59), ROWS(_xlpm.cKeep)), _xlfn.TAKE(IF(_xlpm.cKeep<>"", _xlpm.cKeep, "INPUT NEEDED"), _xlpm.k) ) ) )} | C52: {=_xlfn.LET( _xlpm.gAll, _xlfn.VSTACK(SW!G69:G77, SGC!G55:G63, SIKA!G45:G54, BLANK!G31:G40), _xlpm.fAll, _xlfn.VSTACK(SW!F69:F77, SGC!F55:F63, SIKA!F45:F54, BLANK!F31:F40), _xlpm.srcAll, _xlfn.VSTACK( _xlfn.MAKEARRAY(ROWS(SW!G69:G77),1,_xlfn.LAMBDA(_xlpm.r,_xlpm.c,"SW")), _xlfn.MAKEARRAY(ROWS(SGC!G55:G63),1,_xlfn.LAMBDA(_xlpm.r,_xlpm.c,"RIO")), _xlfn.MAKEARRAY(ROWS(SIKA!G45:G54),1,_xlfn.LAMBDA(_xlpm.r,_xlpm.c,"SIKA")), _xlfn.MAKEARRAY(ROWS(BLANK!G31:G40),1,_xlfn.LAMBDA(_xlpm.r,_xlpm.c,"BLANK")) ), _xlpm.mask, (_xlpm.gAll<>"")+(_xlpm.fAll<>""), _xlpm.sKeep, _xlfn._xlws.FILTER(_xlpm.srcAll, _xlpm.mask), IF(SUM(_xlpm.mask)=0, "", _xlfn.TAKE(_xlpm.sKeep, MIN(ROWS(_xlfn.ANCHORARRAY(B52)), ROWS(_xlpm.sKeep))) ) )} | F52: {=_xlfn.LET( _xlpm.gAll, _xlfn.VSTACK(SW!G69:G77, SGC!G55:G63, SIKA!G45:G54, BLANK!G31:G40), _xlpm.fAll, _xlfn.VSTACK(SW!F69:F77, SGC!F55:F63, SIKA!F45:F54, BLANK!F31:F40), _xlpm.mask, (_xlpm.gAll<>"")+(_xlpm.fAll<>""), _xlpm.n, SUM(--_xlpm.mask), IF(_xlpm.n=0, "", _xlfn.LET( _xlpm.fKeep, _xlfn._xlws.FILTER(_xlpm.fAll, _xlpm.mask), _xlpm.k, MIN(ROWS(F50:F59), ROWS(_xlpm.fKeep)), _xlfn.TAKE(IF(_xlpm.fKeep<>"", _xlpm.fKeep, "INPUT REQ."), _xlpm.k) ) ) )} | G52: {=_xlfn.LET( _xlpm.gAll, _xlfn.VSTACK(SW!G69:G77, SGC!G55:G63, SIKA!G45:G54, BLANK!G31:G40), _xlpm.fAll, _xlfn.VSTACK(SW!F69:F77, SGC!F55:F63, SIKA!F45:F54, BLANK!F31:F40), _xlpm.mask, (_xlpm.gAll<>"")+(_xlpm.fAll<>""), _xlpm.n, SUM(--_xlpm.mask), IF(_xlpm.n=0, "", _xlfn.LET( _xlpm.gKeep, _xlfn._xlws.FILTER(_xlpm.gAll, _xlpm.mask), _xlpm.k, MIN(ROWS(H50:H59), ROWS(_xlpm.gKeep)), _xlfn.TAKE(IF(_xlpm.gKeep<>"", _xlpm.gKeep, "INPUT REQ."), _xlpm.k) ) ) )} | H52: {=_xlfn.LET( _xlpm.gAll, _xlfn.VSTACK(SW!G69:G77, SGC!G55:G63, SIKA!G45:G54, BLANK!G31:G40), _xlpm.fAll, _xlfn.VSTACK(SW!F69:F77, SGC!F55:F63, SIKA!F45:F54, BLANK!F31:F40), _xlpm.hAll, _xlfn.VSTACK(SW!H69:H77, SGC!H55:H63, SIKA!H45:H54, BLANK!H31:H40), _xlpm.mask, (_xlpm.gAll<>"")+(_xlpm.fAll<>""), _xlpm.n, SUM(_xlpm.mask), IF(_xlpm.n=0, "", _xlfn.LET( _xlpm.hKeep, _xlfn._xlws.FILTER(_xlpm.hAll, _xlpm.mask), _xlfn.TAKE(_xlpm.hKeep, MIN(ROWS(I50:I56), ROWS(_xlpm.hKeep))) ) ) )} | I52: =_xlfn.LET(_xlpm.a, N(G52:G61), _xlpm.b, N(F52:F61), _xlpm.p, _xlpm.a*_xlpm.b, IF(_xlpm.p=0, "", _xlpm.p))
I53: =_xlfn.LET(_xlpm.a, N(G53:G62), _xlpm.b, N(F53:F62), _xlpm.p, _xlpm.a*_xlpm.b, IF(_xlpm.p=0, "", _xlpm.p))
I54: =_xlfn.LET(_xlpm.a, N(G54:G63), _xlpm.b, N(F54:F63), _xlpm.p, _xlpm.a*_xlpm.b, IF(_xlpm.p=0, "", _xlpm.p))
I55: =_xlfn.LET(_xlpm.a, N(G55:G64), _xlpm.b, N(F55:F64), _xlpm.p, _xlpm.a*_xlpm.b, IF(_xlpm.p=0, "", _xlpm.p))
